Workbook

Sheet Date Inițiale
A1: Solul | C1: Specificații | G1: Cultura | H1: Note de bonitare
A2: Alunecări | B2: Absente | H2: Generală | I2: Alunecări | J2: Panta | K2: Temperatura medie anuală | L2: Precipitații | M2: Salinizarea/Alcalizarea | N2: Gleizarea | O2: Pseudogleizarea | P2: Adâncimea apelor freatice | Q2: Textura | R2: Volumul edafic util | S2: Porozitatea | T2: pH | U2: Rezerva de humus | V2: Conținutul de carbonați
A3: Panta | B3: P≤5% | C3: Orientarea | D3: S | G3: PS (Pășuni) | H3: =PRODUCT(I3:V3) -> 0.81 | I3: =HLOOKUP($B$2,Alunecări!$B$2:$E$26,Sheet2!B3,0) -> 1 | J3: =HLOOKUP($B$3,Panta!$B$2:$F$26,Sheet2!B3,0) -> 1 | K3: =HLOOKUP(MROUND($D$4,0.5),'Temperatura medie anuală'!$B$2:$N$26,Sheet2!B3,TRUE) -> 1 | L3: =HLOOKUP($D$5,IF($D$4<=8,Precipitații!$B$2:$J$26,IF(AND($D$4>8,$D$4<10),Precipitații!$K$2:$S$26,Precipitații!$T$2:$AB$26)),Sheet2!B3,1) -> 0.9 | M3: =HLOOKUP($B$6,'Salinizarea&Alcalizarea'!$B$2:$F$26,Sheet2!B3,0) -> 1 | N3: =HLOOKUP($B$7,IF('Date Inițiale'!$D$7=Sheet2!$E$3,Gleizarea!$B$2:$I$26,Gleizarea!$J$2:$Q$26),Sheet2!B3,0) -> 1 | O3: =HLOOKUP($B$8,Pseudogleizare!$B$2:$H$26,Sheet2!B3,0) -> 1 | P3: =HLOOKUP($B$9,IF(OR($B$10=Textura!$B$3,$B$10=Textura!$C$3),'Adâncimea apelor freatice'!$C$2:$J$26,IF(OR($B$10=Textura!$D$3,$B$10=Textura!$F$3),'Adâncimea apelor freatice'!$K$2:$R$26,'Adâncimea apelor freatice'!$S$2:$Z$26)),Sheet2!B3,0) -> 1 | Q3: =HLOOKUP($B$10,IF(OR($B$12=Porozitatea!$D$3,Porozitatea!$E$3,Porozitatea!$F$3),Textura!$B$3:$L$27,Textura!$M$3:$W$27),Sheet2!B3,0) -> 1 | R3: =HLOOKUP($B$11,IF($B$5<600,'Volumul edafic util'!$B$3:$G$27,'Volumul edafic util'!$H$3:$M$27),Sheet2!B3,0) -> 1 | S3: =HLOOKUP($B$12,IF(OR($B$10=Textura!$B$3,$B$10=Textura!C3,$B$10=Textura!D3,$B$10=Textura!$E$3,$B$10=Textura!$I$3,$B$10=Textura!$J$3,$B$10=Textura!$K$3),Porozitatea!$B$3:$F$27,Porozitatea!$G$3:$K$27),Sheet2!B3,0) -> 0.9 | T3: =HLOOKUP($B$13,IF($D$13=Sheet2!$F$3,pH!$B$3:$J$27,pH!$K$3:$X$27),Sheet2!B3,0) -> 1 | U3: =HLOOKUP($B$14,IF(OR($B$10=Textura!$D$3,$B$10=Textura!$E$3,$B$10=Textura!$F$3,$B$10=Textura!$G$3,$B$10=Textura!$H$3,$B$10=Textura!$L$3),'Rezerva de humus'!$L$3:$U$27,'Rezerva de humus'!$B$3:$K$27),Sheet2!B3,0) -> 1 | V3: =HLOOKUP($B$15,'Conținutul de carbonați'!$B$2:$H$26,Sheet2!B3,0) -> 1
A4: Temperatura medie anuală | B4: 10.25 | C4: Corectată | D4: =B4*'Temperatura medie anuală'!P42 -> 10.25 | G4: FN (Fânețe) | H4: =PRODUCT(I4:V4) -> 0.648 | I4: =HLOOKUP($B$2,Alunecări!$B$2:$E$26,Sheet2!B4,0) -> 1 | J4: =HLOOKUP($B$3,Panta!$B$2:$F$26,Sheet2!B4,0) -> 1 | K4: =HLOOKUP(MROUND($D$4,0.5),'Temperatura medie anuală'!$B$2:$N$26,Sheet2!B4,TRUE) -> 1 | L4: =HLOOKUP($D$5,IF($D$4<=8,Precipitații!$B$2:$J$26,IF(AND($D$4>8,$D$4<10),Precipitații!$K$2:$S$26,Precipitații!$T$2:$AB$26)),Sheet2!B4,1) -> 0.8 | M4: =HLOOKUP($B$6,'Salinizarea&Alcalizarea'!$B$2:$F$26,Sheet2!B4,0) -> 1 | N4: =HLOOKUP($B$7,IF('Date Inițiale'!$D$7=Sheet2!$E$3,Gleizarea!$B$2:$I$26,Gleizarea!$J$2:$Q$26),Sheet2!B4,0) -> 1 | O4: =HLOOKUP($B$8,Pseudogleizare!$B$2:$H$26,Sheet2!B4,0) -> 1 | P4: =HLOOKUP($B$9,IF(OR($B$10=Textura!$B$3,$B$10=Textura!$C$3),'Adâncimea apelor freatice'!$C$2:$J$26,IF(OR($B$10=Textura!$D$3,$B$10=Textura!$F$3),'Adâncimea apelor freatice'!$K$2:$R$26,'Adâncimea apelor freatice'!$S$2:$Z$26)),Sheet2!B4,0) -> 0.9 | Q4: =HLOOKUP($B$10,IF(OR($B$12=Porozitatea!$D$3,Porozitatea!$E$3,Porozitatea!$F$3),Textura!$B$3:$L$27,Textura!$M$3:$W$27),Sheet2!B4,0) -> 1 | R4: =HLOOKUP($B$11,IF($B$5<600,'Volumul edafic util'!$B$3:$G$27,'Volumul edafic util'!$H$3:$M$27),Sheet2!B4,0) -> 1 | S4: =HLOOKUP($B$12,IF(OR($B$10=Textura!$B$3,$B$10=Textura!C4,$B$10=Textura!D4,$B$10=Textura!$E$3,$B$10=Textura!$I$3,$B$10=Textura!$J$3,$B$10=Textura!$K$3),Porozitatea!$B$3:$F$27,Porozitatea!$G$3:$K$27),Sheet2!B4,0) -> 0.9 | T4: =HLOOKUP($B$13,IF($D$13=Sheet2!$F$3,pH!$B$3:$J$27,pH!$K$3:$X$27),Sheet2!B4,0) -> 1 | U4: =HLOOKUP($B$14,IF(OR($B$10=Textura!$D$3,$B$10=Textura!$E$3,$B$10=Textura!$F$3,$B$10=Textura!$G$3,$B$10=Textura!$H$3,$B$10=Textura!$L$3),'Rezerva de humus'!$L$3:$U$27,'Rezerva de humus'!$B$3:$K$27),Sheet2!B4,0) -> 1 | V4: =HLOOKUP($B$15,'Conținutul de carbonați'!$B$2:$H$26,Sheet2!B4,0) -> 1
A5: Precipitații | B5: 655 | C5: Corectată | D5: =MROUND(B5,25) -> 650 | G5: MR (Măr) | H5: =PRODUCT(I5:V5) -> 0.9 | I5: =HLOOKUP($B$2,Alunecări!$B$2:$E$26,Sheet2!B5,0) -> 1 | J5: =HLOOKUP($B$3,Panta!$B$2:$F$26,Sheet2!B5,0) -> 1 | K5: =HLOOKUP(MROUND($D$4,0.5),'Temperatura medie anuală'!$B$2:$N$26,Sheet2!B5,TRUE) -> 1 | L5: =HLOOKUP($D$5,IF($D$4<=8,Precipitații!$B$2:$J$26,IF(AND($D$4>8,$D$4<10),Precipitații!$K$2:$S$26,Precipitații!$T$2:$AB$26)),Sheet2!B5,1) -> 1 | M5: =HLOOKUP($B$6,'Salinizarea&Alcalizarea'!$B$2:$F$26,Sheet2!B5,0) -> 1 | N5: =HLOOKUP($B$7,IF('Date Inițiale'!$D$7=Sheet2!$E$3,Gleizarea!$B$2:$I$26,Gleizarea!$J$2:$Q$26),Sheet2!B5,0) -> 1 | O5: =HLOOKUP($B$8,Pseudogleizare!$B$2:$H$26,Sheet2!B5,0) -> 1 | P5: =HLOOKUP($B$9,IF(OR($B$10=Textura!$B$3,$B$10=Textura!$C$3),'Adâncimea apelor freatice'!$C$2:$J$26,IF(OR($B$10=Textura!$D$3,$B$10=Textura!$F$3),'Adâncimea apelor freatice'!$K$2:$R$26,'Adâncimea apelor freatice'!$S$2:$Z$26)),Sheet2!B5,0) -> 0.9 | Q5: =HLOOKUP($B$10,IF(OR($B$12=Porozitatea!$D$3,Porozitatea!$E$3,Porozitatea!$F$3),Textura!$B$3:$L$27,Textura!$M$3:$W$27),Sheet2!B5,0) -> 1 | R5: =HLOOKUP($B$11,IF($B$5<600,'Volumul edafic util'!$B$3:$G$27,'Volumul edafic util'!$H$3:$M$27),Sheet2!B5,0) -> 1 | S5: =HLOOKUP($B$12,IF(OR($B$10=Textura!$B$3,$B$10=Textura!C5,$B$10=Textura!D5,$B$10=Textura!$E$3,$B$10=Textura!$I$3,$B$10=Textura!$J$3,$B$10=Textura!$K$3),Porozitatea!$B$3:$F$27,Porozitatea!$G$3:$K$27),Sheet2!B5,0) -> 1 | T5: =HLOOKUP($B$13,IF($D$13=Sheet2!$F$3,pH!$B$3:$J$27,pH!$K$3:$X$27),Sheet2!B5,0) -> 1 | U5: =HLOOKUP($B$14,IF(OR($B$10=Textura!$D$3,$B$10=Textura!$E$3,$B$10=Textura!$F$3,$B$10=Textura!$G$3,$B$10=Textura!$H$3,$B$10=Textura!$L$3),'Rezerva de humus'!$L$3:$U$27,'Rezerva de humus'!$B$3:$K$27),Sheet2!B5,0) -> 1 | V5: =HLOOKUP($B$15,'Conținutul de carbonați'!$B$2:$H$26,Sheet2!B5,0) -> 1
A6: Salinizarea/Alcalizarea | B6: Nesalinizat/-alcalizat | G6: PR (Păr) | H6: =PRODUCT(I6:V6) -> 1 | I6: =HLOOKUP($B$2,Alunecări!$B$2:$E$26,Sheet2!B6,0) -> 1 | J6: =HLOOKUP($B$3,Panta!$B$2:$F$26,Sheet2!B6,0) -> 1 | K6: =HLOOKUP(MROUND($D$4,0.5),'Temperatura medie anuală'!$B$2:$N$26,Sheet2!B6,TRUE) -> 1 | L6: =HLOOKUP($D$5,IF($D$4<=8,Precipitații!$B$2:$J$26,IF(AND($D$4>8,$D$4<10),Precipitații!$K$2:$S$26,Precipitații!$T$2:$AB$26)),Sheet2!B6,1) -> 1 | M6: =HLOOKUP($B$6,'Salinizarea&Alcalizarea'!$B$2:$F$26,Sheet2!B6,0) -> 1 | N6: =HLOOKUP($B$7,IF('Date Inițiale'!$D$7=Sheet2!$E$3,Gleizarea!$B$2:$I$26,Gleizarea!$J$2:$Q$26),Sheet2!B6,0) -> 1 | O6: =HLOOKUP($B$8,Pseudogleizare!$B$2:$H$26,Sheet2!B6,0) -> 1 | P6: =HLOOKUP($B$9,IF(OR($B$10=Textura!$B$3,$B$10=Textura!$C$3),'Adâncimea apelor freatice'!$C$2:$J$26,IF(OR($B$10=Textura!$D$3,$B$10=Textura!$F$3),'Adâncimea apelor freatice'!$K$2:$R$26,'Adâncimea apelor freatice'!$S$2:$Z$26)),Sheet2!B6,0) -> 1 | Q6: =HLOOKUP($B$10,IF(OR($B$12=Porozitatea!$D$3,Porozitatea!$E$3,Porozitatea!$F$3),Textura!$B$3:$L$27,Textura!$M$3:$W$27),Sheet2!B6,0) -> 1 | R6: =HLOOKUP($B$11,IF($B$5<600,'Volumul edafic util'!$B$3:$G$27,'Volumul edafic util'!$H$3:$M$27),Sheet2!B6,0) -> 1 | S6: =HLOOKUP($B$12,IF(OR($B$10=Textura!$B$3,$B$10=Textura!C6,$B$10=Textura!D6,$B$10=Textura!$E$3,$B$10=Textura!$I$3,$B$10=Textura!$J$3,$B$10=Textura!$K$3),Porozitatea!$B$3:$F$27,Porozitatea!$G$3:$K$27),Sheet2!B6,0) -> 1 | T6: =HLOOKUP($B$13,IF($D$13=Sheet2!$F$3,pH!$B$3:$J$27,pH!$K$3:$X$27),Sheet2!B6,0) -> 1 | U6: =HLOOKUP($B$14,IF(OR($B$10=Textura!$D$3,$B$10=Textura!$E$3,$B$10=Textura!$F$3,$B$10=Textura!$G$3,$B$10=Textura!$H$3,$B$10=Textura!$L$3),'Rezerva de humus'!$L$3:$U$27,'Rezerva de humus'!$B$3:$K$27),Sheet2!B6,0) -> 1 | V6: =HLOOKUP($B$15,'Conținutul de carbonați'!$B$2:$H$26,Sheet2!B6,0) -> 1
A7: Gleizarea | B7: Negleizat | C7: Drenaj și/sau desecare | D7: Nu | G7: PN (Prun) | H7: =PRODUCT(I7:V7) -> 1 | I7: =HLOOKUP($B$2,Alunecări!$B$2:$E$26,Sheet2!B7,0) -> 1 | J7: =HLOOKUP($B$3,Panta!$B$2:$F$26,Sheet2!B7,0) -> 1 | K7: =HLOOKUP(MROUND($D$4,0.5),'Temperatura medie anuală'!$B$2:$N$26,Sheet2!B7,TRUE) -> 1 | L7: =HLOOKUP($D$5,IF($D$4<=8,Precipitații!$B$2:$J$26,IF(AND($D$4>8,$D$4<10),Precipitații!$K$2:$S$26,Precipitații!$T$2:$AB$26)),Sheet2!B7,1) -> 1 | M7: =HLOOKUP($B$6,'Salinizarea&Alcalizarea'!$B$2:$F$26,Sheet2!B7,0) -> 1 | N7: =HLOOKUP($B$7,IF('Date Inițiale'!$D$7=Sheet2!$E$3,Gleizarea!$B$2:$I$26,Gleizarea!$J$2:$Q$26),Sheet2!B7,0) -> 1 | O7: =HLOOKUP($B$8,Pseudogleizare!$B$2:$H$26,Sheet2!B7,0) -> 1 | P7: =HLOOKUP($B$9,IF(OR($B$10=Textura!$B$3,$B$10=Textura!$C$3),'Adâncimea apelor freatice'!$C$2:$J$26,IF(OR($B$10=Textura!$D$3,$B$10=Textura!$F$3),'Adâncimea apelor freatice'!$K$2:$R$26,'Adâncimea apelor freatice'!$S$2:$Z$26)),Sheet2!B7,0) -> 1 | Q7: =HLOOKUP($B$10,IF(OR($B$12=Porozitatea!$D$3,Porozitatea!$E$3,Porozitatea!$F$3),Textura!$B$3:$L$27,Textura!$M$3:$W$27),Sheet2!B7,0) -> 1 | R7: =HLOOKUP($B$11,IF($B$5<600,'Volumul edafic util'!$B$3:$G$27,'Volumul edafic util'!$H$3:$M$27),Sheet2!B7,0) -> 1 | S7: =HLOOKUP($B$12,IF(OR($B$10=Textura!$B$3,$B$10=Textura!C7,$B$10=Textura!D7,$B$10=Textura!$E$3,$B$10=Textura!$I$3,$B$10=Textura!$J$3,$B$10=Textura!$K$3),Porozitatea!$B$3:$F$27,Porozitatea!$G$3:$K$27),Sheet2!B7,0) -> 1 | T7: =HLOOKUP($B$13,IF($D$13=Sheet2!$F$3,pH!$B$3:$J$27,pH!$K$3:$X$27),Sheet2!B7,0) -> 1 | U7: =HLOOKUP($B$14,IF(OR($B$10=Textura!$D$3,$B$10=Textura!$E$3,$B$10=Textura!$F$3,$B$10=Textura!$G$3,$B$10=Textura!$H$3,$B$10=Textura!$L$3),'Rezerva de humus'!$L$3:$U$27,'Rezerva de humus'!$B$3:$K$27),Sheet2!B7,0) -> 1 | V7: =HLOOKUP($B$15,'Conținutul de carbonați'!$B$2:$H$26,Sheet2!B7,0) -> 1
A8: Pseudogleizarea | B8: Nepseudogleizat | G8: CV (Cireș) | H8: =PRODUCT(I8:V8) -> 1 | I8: =HLOOKUP($B$2,Alunecări!$B$2:$E$26,Sheet2!B8,0) -> 1 | J8: =HLOOKUP($B$3,Panta!$B$2:$F$26,Sheet2!B8,0) -> 1 | K8: =HLOOKUP(MROUND($D$4,0.5),'Temperatura medie anuală'!$B$2:$N$26,Sheet2!B8,TRUE) -> 1 | L8: =HLOOKUP($D$5,IF($D$4<=8,Precipitații!$B$2:$J$26,IF(AND($D$4>8,$D$4<10),Precipitații!$K$2:$S$26,Precipitații!$T$2:$AB$26)),Sheet2!B8,1) -> 1 | M8: =HLOOKUP($B$6,'Salinizarea&Alcalizarea'!$B$2:$F$26,Sheet2!B8,0) -> 1 | N8: =HLOOKUP($B$7,IF('Date Inițiale'!$D$7=Sheet2!$E$3,Gleizarea!$B$2:$I$26,Gleizarea!$J$2:$Q$26),Sheet2!B8,0) -> 1 | O8: =HLOOKUP($B$8,Pseudogleizare!$B$2:$H$26,Sheet2!B8,0) -> 1 | P8: =HLOOKUP($B$9,IF(OR($B$10=Textura!$B$3,$B$10=Textura!$C$3),'Adâncimea apelor freatice'!$C$2:$J$26,IF(OR($B$10=Textura!$D$3,$B$10=Textura!$F$3),'Adâncimea apelor freatice'!$K$2:$R$26,'Adâncimea apelor freatice'!$S$2:$Z$26)),Sheet2!B8,0) -> 1 | Q8: =HLOOKUP($B$10,IF(OR($B$12=Porozitatea!$D$3,Porozitatea!$E$3,Porozitatea!$F$3),Textura!$B$3:$L$27,Textura!$M$3:$W$27),Sheet2!B8,0) -> 1 | R8: =HLOOKUP($B$11,IF($B$5<600,'Volumul edafic util'!$B$3:$G$27,'Volumul edafic util'!$H$3:$M$27),Sheet2!B8,0) -> 1 | S8: =HLOOKUP($B$12,IF(OR($B$10=Textura!$B$3,$B$10=Textura!C8,$B$10=Textura!D8,$B$10=Textura!$E$3,$B$10=Textura!$I$3,$B$10=Textura!$J$3,$B$10=Textura!$K$3),Porozitatea!$B$3:$F$27,Porozitatea!$G$3:$K$27),Sheet2!B8,0) -> 1 | T8: =HLOOKUP($B$13,IF($D$13=Sheet2!$F$3,pH!$B$3:$J$27,pH!$K$3:$X$27),Sheet2!B8,0) -> 1 | U8: =HLOOKUP($B$14,IF(OR($B$10=Textura!$D$3,$B$10=Textura!$E$3,$B$10=Textura!$F$3,$B$10=Textura!$G$3,$B$10=Textura!$H$3,$B$10=Textura!$L$3),'Rezerva de humus'!$L$3:$U$27,'Rezerva de humus'!$B$3:$K$27),Sheet2!B8,0) -> 1 | V8: =HLOOKUP($B$15,'Conținutul de carbonați'!$B$2:$H$26,Sheet2!B8,0) -> 1
A9: Adâncimea apelor freatice | B9: Mijlocie | G9: CS (Cais) | H9: =PRODUCT(I9:V9) -> 1 | I9: =HLOOKUP($B$2,Alunecări!$B$2:$E$26,Sheet2!B9,0) -> 1 | J9: =HLOOKUP($B$3,Panta!$B$2:$F$26,Sheet2!B9,0) -> 1 | K9: =HLOOKUP(MROUND($D$4,0.5),'Temperatura medie anuală'!$B$2:$N$26,Sheet2!B9,TRUE) -> 1 | L9: =HLOOKUP($D$5,IF($D$4<=8,Precipitații!$B$2:$J$26,IF(AND($D$4>8,$D$4<10),Precipitații!$K$2:$S$26,Precipitații!$T$2:$AB$26)),Sheet2!B9,1) -> 1 | M9: =HLOOKUP($B$6,'Salinizarea&Alcalizarea'!$B$2:$F$26,Sheet2!B9,0) -> 1 | N9: =HLOOKUP($B$7,IF('Date Inițiale'!$D$7=Sheet2!$E$3,Gleizarea!$B$2:$I$26,Gleizarea!$J$2:$Q$26),Sheet2!B9,0) -> 1 | O9: =HLOOKUP($B$8,Pseudogleizare!$B$2:$H$26,Sheet2!B9,0) -> 1 | P9: =HLOOKUP($B$9,IF(OR($B$10=Textura!$B$3,$B$10=Textura!$C$3),'Adâncimea apelor freatice'!$C$2:$J$26,IF(OR($B$10=Textura!$D$3,$B$10=Textura!$F$3),'Adâncimea apelor freatice'!$K$2:$R$26,'Adâncimea apelor freatice'!$S$2:$Z$26)),Sheet2!B9,0) -> 1 | Q9: =HLOOKUP($B$10,IF(OR($B$12=Porozitatea!$D$3,Porozitatea!$E$3,Porozitatea!$F$3),Textura!$B$3:$L$27,Textura!$M$3:$W$27),Sheet2!B9,0) -> 1 | R9: =HLOOKUP($B$11,IF($B$5<600,'Volumul edafic util'!$B$3:$G$27,'Volumul edafic util'!$H$3:$M$27),Sheet2!B9,0) -> 1 | S9: =HLOOKUP($B$12,IF(OR($B$10=Textura!$B$3,$B$10=Textura!C9,$B$10=Textura!D9,$B$10=Textura!$E$3,$B$10=Textura!$I$3,$B$10=Textura!$J$3,$B$10=Textura!$K$3),Porozitatea!$B$3:$F$27,Porozitatea!$G$3:$K$27),Sheet2!B9,0) -> 1 | T9: =HLOOKUP($B$13,IF($D$13=Sheet2!$F$3,pH!$B$3:$J$27,pH!$K$3:$X$27),Sheet2!B9,0) -> 1 | U9: =HLOOKUP($B$14,IF(OR($B$10=Textura!$D$3,$B$10=Textura!$E$3,$B$10=Textura!$F$3,$B$10=Textura!$G$3,$B$10=Textura!$H$3,$B$10=Textura!$L$3),'Rezerva de humus'!$L$3:$U$27,'Rezerva de humus'!$B$3:$K$27),Sheet2!B9,0) -> 1 | V9: =HLOOKUP($B$15,'Conținutul de carbonați'!$B$2:$H$26,Sheet2!B9,0) -> 1
A10: Textura | B10: Lutoasă (≥55% 0,01mm+) | G10: PC (Piersic) | H10: =PRODUCT(I10:V10) -> 1 | I10: =HLOOKUP($B$2,Alunecări!$B$2:$E$26,Sheet2!B10,0) -> 1 | J10: =HLOOKUP($B$3,Panta!$B$2:$F$26,Sheet2!B10,0) -> 1 | K10: =HLOOKUP(MROUND($D$4,0.5),'Temperatura medie anuală'!$B$2:$N$26,Sheet2!B10,TRUE) -> 1 | L10: =HLOOKUP($D$5,IF($D$4<=8,Precipitații!$B$2:$J$26,IF(AND($D$4>8,$D$4<10),Precipitații!$K$2:$S$26,Precipitații!$T$2:$AB$26)),Sheet2!B10,1) -> 1 | M10: =HLOOKUP($B$6,'Salinizarea&Alcalizarea'!$B$2:$F$26,Sheet2!B10,0) -> 1 | N10: =HLOOKUP($B$7,IF('Date Inițiale'!$D$7=Sheet2!$E$3,Gleizarea!$B$2:$I$26,Gleizarea!$J$2:$Q$26),Sheet2!B10,0) -> 1 | O10: =HLOOKUP($B$8,Pseudogleizare!$B$2:$H$26,Sheet2!B10,0) -> 1 | P10: =HLOOKUP($B$9,IF(OR($B$10=Textura!$B$3,$B$10=Textura!$C$3),'Adâncimea apelor freatice'!$C$2:$J$26,IF(OR($B$10=Textura!$D$3,$B$10=Textura!$F$3),'Adâncimea apelor freatice'!$K$2:$R$26,'Adâncimea apelor freatice'!$S$2:$Z$26)),Sheet2!B10,0) -> 1 | Q10: =HLOOKUP($B$10,IF(OR($B$12=Porozitatea!$D$3,Porozitatea!$E$3,Porozitatea!$F$3),Textura!$B$3:$L$27,Textura!$M$3:$W$27),Sheet2!B10,0) -> 1 | R10: =HLOOKUP($B$11,IF($B$5<600,'Volumul edafic util'!$B$3:$G$27,'Volumul edafic util'!$H$3:$M$27),Sheet2!B10,0) -> 1 | S10: =HLOOKUP($B$12,IF(OR($B$10=Textura!$B$3,$B$10=Textura!C10,$B$10=Textura!D10,$B$10=Textura!$E$3,$B$10=Textura!$I$3,$B$10=Textura!$J$3,$B$10=Textura!$K$3),Porozitatea!$B$3:$F$27,Porozitatea!$G$3:$K$27),Sheet2!B10,0) -> 1 | T10: =HLOOKUP($B$13,IF($D$13=Sheet2!$F$3,pH!$B$3:$J$27,pH!$K$3:$X$27),Sheet2!B10,0) -> 1 | U10: =HLOOKUP($B$14,IF(OR($B$10=Textura!$D$3,$B$10=Textura!$E$3,$B$10=Textura!$F$3,$B$10=Textura!$G$3,$B$10=Textura!$H$3,$B$10=Textura!$L$3),'Rezerva de humus'!$L$3:$U$27,'Rezerva de humus'!$B$3:$K$27),Sheet2!B10,0) -> 1 | V10: =HLOOKUP($B$15,'Conținutul de carbonați'!$B$2:$H$26,Sheet2!B10,0) -> 1
A11: Volumul edafic util | B11: 75%<V≤100% | G11: VV (Vie-vin) | H11: =PRODUCT(I11:V11) -> 1 | I11: =HLOOKUP($B$2,Alunecări!$B$2:$E$26,Sheet2!B11,0) -> 1 | J11: =HLOOKUP($B$3,Panta!$B$2:$F$26,Sheet2!B11,0) -> 1 | K11: =HLOOKUP(MROUND($D$4,0.5),'Temperatura medie anuală'!$B$2:$N$26,Sheet2!B11,TRUE) -> 1 | L11: =HLOOKUP($D$5,IF($D$4<=8,Precipitații!$B$2:$J$26,IF(AND($D$4>8,$D$4<10),Precipitații!$K$2:$S$26,Precipitații!$T$2:$AB$26)),Sheet2!B11,1) -> 1 | M11: =HLOOKUP($B$6,'Salinizarea&Alcalizarea'!$B$2:$F$26,Sheet2!B11,0) -> 1 | N11: =HLOOKUP($B$7,IF('Date Inițiale'!$D$7=Sheet2!$E$3,Gleizarea!$B$2:$I$26,Gleizarea!$J$2:$Q$26),Sheet2!B11,0) -> 1 | O11: =HLOOKUP($B$8,Pseudogleizare!$B$2:$H$26,Sheet2!B11,0) -> 1 | P11: =HLOOKUP($B$9,IF(OR($B$10=Textura!$B$3,$B$10=Textura!$C$3),'Adâncimea apelor freatice'!$C$2:$J$26,IF(OR($B$10=Textura!$D$3,$B$10=Textura!$F$3),'Adâncimea apelor freatice'!$K$2:$R$26,'Adâncimea apelor freatice'!$S$2:$Z$26)),Sheet2!B11,0) -> 1 | Q11: =HLOOKUP($B$10,IF(OR($B$12=Porozitatea!$D$3,Porozitatea!$E$3,Porozitatea!$F$3),Textura!$B$3:$L$27,Textura!$M$3:$W$27),Sheet2!B11,0) -> 1 | R11: =HLOOKUP($B$11,IF($B$5<600,'Volumul edafic util'!$B$3:$G$27,'Volumul edafic util'!$H$3:$M$27),Sheet2!B11,0) -> 1 | S11: =HLOOKUP($B$12,IF(OR($B$10=Textura!$B$3,$B$10=Textura!C11,$B$10=Textura!D11,$B$10=Textura!$E$3,$B$10=Textura!$I$3,$B$10=Textura!$J$3,$B$10=Textura!$K$3),Porozitatea!$B$3:$F$27,Porozitatea!$G$3:$K$27),Sheet2!B11,0) -> 1 | T11: =HLOOKUP($B$13,IF($D$13=Sheet2!$F$3,pH!$B$3:$J$27,pH!$K$3:$X$27),Sheet2!B11,0) -> 1 | U11: =HLOOKUP($B$14,IF(OR($B$10=Textura!$D$3,$B$10=Textura!$E$3,$B$10=Textura!$F$3,$B$10=Textura!$G$3,$B$10=Textura!$H$3,$B$10=Textura!$L$3),'Rezerva de humus'!$L$3:$U$27,'Rezerva de humus'!$B$3:$K$27),Sheet2!B11,0) -> 1 | V11: =HLOOKUP($B$15,'Conținutul de carbonați'!$B$2:$H$26,Sheet2!B11,0) -> 1
A12: Porozitatea | B12: P≥85% | G12: VM (Vie-masă) | H12: =PRODUCT(I12:V12) -> 1 | I12: =HLOOKUP($B$2,Alunecări!$B$2:$E$26,Sheet2!B12,0) -> 1 | J12: =HLOOKUP($B$3,Panta!$B$2:$F$26,Sheet2!B12,0) -> 1 | K12: =HLOOKUP(MROUND($D$4,0.5),'Temperatura medie anuală'!$B$2:$N$26,Sheet2!B12,TRUE) -> 1 | L12: =HLOOKUP($D$5,IF($D$4<=8,Precipitații!$B$2:$J$26,IF(AND($D$4>8,$D$4<10),Precipitații!$K$2:$S$26,Precipitații!$T$2:$AB$26)),Sheet2!B12,1) -> 1 | M12: =HLOOKUP($B$6,'Salinizarea&Alcalizarea'!$B$2:$F$26,Sheet2!B12,0) -> 1 | N12: =HLOOKUP($B$7,IF('Date Inițiale'!$D$7=Sheet2!$E$3,Gleizarea!$B$2:$I$26,Gleizarea!$J$2:$Q$26),Sheet2!B12,0) -> 1 | O12: =HLOOKUP($B$8,Pseudogleizare!$B$2:$H$26,Sheet2!B12,0) -> 1 | P12: =HLOOKUP($B$9,IF(OR($B$10=Textura!$B$3,$B$10=Textura!$C$3),'Adâncimea apelor freatice'!$C$2:$J$26,IF(OR($B$10=Textura!$D$3,$B$10=Textura!$F$3),'Adâncimea apelor freatice'!$K$2:$R$26,'Adâncimea apelor freatice'!$S$2:$Z$26)),Sheet2!B12,0) -> 1 | Q12: =HLOOKUP($B$10,IF(OR($B$12=Porozitatea!$D$3,Porozitatea!$E$3,Porozitatea!$F$3),Textura!$B$3:$L$27,Textura!$M$3:$W$27),Sheet2!B12,0) -> 1 | R12: =HLOOKUP($B$11,IF($B$5<600,'Volumul edafic util'!$B$3:$G$27,'Volumul edafic util'!$H$3:$M$27),Sheet2!B12,0) -> 1 | S12: =HLOOKUP($B$12,IF(OR($B$10=Textura!$B$3,$B$10=Textura!C12,$B$10=Textura!D12,$B$10=Textura!$E$3,$B$10=Textura!$I$3,$B$10=Textura!$J$3,$B$10=Textura!$K$3),Porozitatea!$B$3:$F$27,Porozitatea!$G$3:$K$27),Sheet2!B12,0) -> 1 | T12: =HLOOKUP($B$13,IF($D$13=Sheet2!$F$3,pH!$B$3:$J$27,pH!$K$3:$X$27),Sheet2!B12,0) -> 1 | U12: =HLOOKUP($B$14,IF(OR($B$10=Textura!$D$3,$B$10=Textura!$E$3,$B$10=Textura!$F$3,$B$10=Textura!$G$3,$B$10=Textura!$H$3,$B$10=Textura!$L$3),'Rezerva de humus'!$L$3:$U$27,'Rezerva de humus'!$B$3:$K$27),Sheet2!B12,0) -> 1 | V12: =HLOOKUP($B$15,'Conținutul de carbonați'!$B$2:$H$26,Sheet2!B12,0) -> 1
A13: pH | B13: pH≤3,5 | C13: Adâncimea saturației | D13: Soluri cu grad de saturație în primii 20 de cm sau în Ap>55% | G13: GR (Grâu) | H13: =PRODUCT(I13:V13) -> 0.8 | I13: =HLOOKUP($B$2,Alunecări!$B$2:$E$26,Sheet2!B13,0) -> 1 | J13: =HLOOKUP($B$3,Panta!$B$2:$F$26,Sheet2!B13,0) -> 1 | K13: =HLOOKUP(MROUND($D$4,0.5),'Temperatura medie anuală'!$B$2:$N$26,Sheet2!B13,TRUE) -> 1 | L13: =HLOOKUP($D$5,IF($D$4<=8,Precipitații!$B$2:$J$26,IF(AND($D$4>8,$D$4<10),Precipitații!$K$2:$S$26,Precipitații!$T$2:$AB$26)),Sheet2!B13,1) -> 1 | M13: =HLOOKUP($B$6,'Salinizarea&Alcalizarea'!$B$2:$F$26,Sheet2!B13,0) -> 1 | N13: =HLOOKUP($B$7,IF('Date Inițiale'!$D$7=Sheet2!$E$3,Gleizarea!$B$2:$I$26,Gleizarea!$J$2:$Q$26),Sheet2!B13,0) -> 1 | O13: =HLOOKUP($B$8,Pseudogleizare!$B$2:$H$26,Sheet2!B13,0) -> 1 | P13: =HLOOKUP($B$9,IF(OR($B$10=Textura!$B$3,$B$10=Textura!$C$3),'Adâncimea apelor freatice'!$C$2:$J$26,IF(OR($B$10=Textura!$D$3,$B$10=Textura!$F$3),'Adâncimea apelor freatice'!$K$2:$R$26,'Adâncimea apelor freatice'!$S$2:$Z$26)),Sheet2!B13,0) -> 1 | Q13: =HLOOKUP($B$10,IF(OR($B$12=Porozitatea!$D$3,Porozitatea!$E$3,Porozitatea!$F$3),Textura!$B$3:$L$27,Textura!$M$3:$W$27),Sheet2!B13,0) -> 1 | R13: =HLOOKUP($B$11,IF($B$5<600,'Volumul edafic util'!$B$3:$G$27,'Volumul edafic util'!$H$3:$M$27),Sheet2!B13,0) -> 1 | S13: =HLOOKUP($B$12,IF(OR($B$10=Textura!$B$3,$B$10=Textura!C13,$B$10=Textura!D13,$B$10=Textura!$E$3,$B$10=Textura!$I$3,$B$10=Textura!$J$3,$B$10=Textura!$K$3),Porozitatea!$B$3:$F$27,Porozitatea!$G$3:$K$27),Sheet2!B13,0) -> 0.8 | T13: =HLOOKUP($B$13,IF($D$13=Sheet2!$F$3,pH!$B$3:$J$27,pH!$K$3:$X$27),Sheet2!B13,0) -> 1 | U13: =HLOOKUP($B$14,IF(OR($B$10=Textura!$D$3,$B$10=Textura!$E$3,$B$10=Textura!$F$3,$B$10=Textura!$G$3,$B$10=Textura!$H$3,$B$10=Textura!$L$3),'Rezerva de humus'!$L$3:$U$27,'Rezerva de humus'!$B$3:$K$27),Sheet2!B13,0) -> 1 | V13: =HLOOKUP($B$15,'Conținutul de carbonați'!$B$2:$H$26,Sheet2!B13,0) -> 1
A14: Rezerva de humus | B14: 160≤H<200 | G14: OR (Orz) | H14: =PRODUCT(I14:V14) -> 0.9 | I14: =HLOOKUP($B$2,Alunecări!$B$2:$E$26,Sheet2!B14,0) -> 1 | J14: =HLOOKUP($B$3,Panta!$B$2:$F$26,Sheet2!B14,0) -> 1 | K14: =HLOOKUP(MROUND($D$4,0.5),'Temperatura medie anuală'!$B$2:$N$26,Sheet2!B14,TRUE) -> 1 | L14: =HLOOKUP($D$5,IF($D$4<=8,Precipitații!$B$2:$J$26,IF(AND($D$4>8,$D$4<10),Precipitații!$K$2:$S$26,Precipitații!$T$2:$AB$26)),Sheet2!B14,1) -> 1 | M14: =HLOOKUP($B$6,'Salinizarea&Alcalizarea'!$B$2:$F$26,Sheet2!B14,0) -> 1 | N14: =HLOOKUP($B$7,IF('Date Inițiale'!$D$7=Sheet2!$E$3,Gleizarea!$B$2:$I$26,Gleizarea!$J$2:$Q$26),Sheet2!B14,0) -> 1 | O14: =HLOOKUP($B$8,Pseudogleizare!$B$2:$H$26,Sheet2!B14,0) -> 1 | P14: =HLOOKUP($B$9,IF(OR($B$10=Textura!$B$3,$B$10=Textura!$C$3),'Adâncimea apelor freatice'!$C$2:$J$26,IF(OR($B$10=Textura!$D$3,$B$10=Textura!$F$3),'Adâncimea apelor freatice'!$K$2:$R$26,'Adâncimea apelor freatice'!$S$2:$Z$26)),Sheet2!B14,0) -> 1 | Q14: =HLOOKUP($B$10,IF(OR($B$12=Porozitatea!$D$3,Porozitatea!$E$3,Porozitatea!$F$3),Textura!$B$3:$L$27,Textura!$M$3:$W$27),Sheet2!B14,0) -> 1 | R14: =HLOOKUP($B$11,IF($B$5<600,'Volumul edafic util'!$B$3:$G$27,'Volumul edafic util'!$H$3:$M$27),Sheet2!B14,0) -> 1 | S14: =HLOOKUP($B$12,IF(OR($B$10=Textura!$B$3,$B$10=Textura!C14,$B$10=Textura!D14,$B$10=Textura!$E$3,$B$10=Textura!$I$3,$B$10=Textura!$J$3,$B$10=Textura!$K$3),Porozitatea!$B$3:$F$27,Porozitatea!$G$3:$K$27),Sheet2!B14,0) -> 0.9 | T14: =HLOOKUP($B$13,IF($D$13=Sheet2!$F$3,pH!$B$3:$J$27,pH!$K$3:$X$27),Sheet2!B14,0) -> 1 | U14: =HLOOKUP($B$14,IF(OR($B$10=Textura!$D$3,$B$10=Textura!$E$3,$B$10=Textura!$F$3,$B$10=Textura!$G$3,$B$10=Textura!$H$3,$B$10=Textura!$L$3),'Rezerva de humus'!$L$3:$U$27,'Rezerva de humus'!$B$3:$K$27),Sheet2!B14,0) -> 1 | V14: =HLOOKUP($B$15,'Conținutul de carbonați'!$B$2:$H$26,Sheet2!B14,0) -> 1
A15: Conținutul de carbonați | B15: CaCO3≤4 | G15: PB (Porumb) | H15: =PRODUCT(I15:V15) -> 0.9 | I15: =HLOOKUP($B$2,Alunecări!$B$2:$E$26,Sheet2!B15,0) -> 1 | J15: =HLOOKUP($B$3,Panta!$B$2:$F$26,Sheet2!B15,0) -> 1 | K15: =HLOOKUP(MROUND($D$4,0.5),'Temperatura medie anuală'!$B$2:$N$26,Sheet2!B15,TRUE) -> 1 | L15: =HLOOKUP($D$5,IF($D$4<=8,Precipitații!$B$2:$J$26,IF(AND($D$4>8,$D$4<10),Precipitații!$K$2:$S$26,Precipitații!$T$2:$AB$26)),Sheet2!B15,1) -> 1 | M15: =HLOOKUP($B$6,'Salinizarea&Alcalizarea'!$B$2:$F$26,Sheet2!B15,0) -> 1 | N15: =HLOOKUP($B$7,IF('Date Inițiale'!$D$7=Sheet2!$E$3,Gleizarea!$B$2:$I$26,Gleizarea!$J$2:$Q$26),Sheet2!B15,0) -> 1 | O15: =HLOOKUP($B$8,Pseudogleizare!$B$2:$H$26,Sheet2!B15,0) -> 1 | P15: =HLOOKUP($B$9,IF(OR($B$10=Textura!$B$3,$B$10=Textura!$C$3),'Adâncimea apelor freatice'!$C$2:$J$26,IF(OR($B$10=Textura!$D$3,$B$10=Textura!$F$3),'Adâncimea apelor freatice'!$K$2:$R$26,'Adâncimea apelor freatice'!$S$2:$Z$26)),Sheet2!B15,0) -> 1 | Q15: =HLOOKUP($B$10,IF(OR($B$12=Porozitatea!$D$3,Porozitatea!$E$3,Porozitatea!$F$3),Textura!$B$3:$L$27,Textura!$M$3:$W$27),Sheet2!B15,0) -> 1 | R15: =HLOOKUP($B$11,IF($B$5<600,'Volumul edafic util'!$B$3:$G$27,'Volumul edafic util'!$H$3:$M$27),Sheet2!B15,0) -> 1 | S15: =HLOOKUP($B$12,IF(OR($B$10=Textura!$B$3,$B$10=Textura!C15,$B$10=Textura!D15,$B$10=Textura!$E$3,$B$10=Textura!$I$3,$B$10=Textura!$J$3,$B$10=Textura!$K$3),Porozitatea!$B$3:$F$27,Porozitatea!$G$3:$K$27),Sheet2!B15,0) -> 0.9 | T15: =HLOOKUP($B$13,IF($D$13=Sheet2!$F$3,pH!$B$3:$J$27,pH!$K$3:$X$27),Sheet2!B15,0) -> 1 | U15: =HLOOKUP($B$14,IF(OR($B$10=Textura!$D$3,$B$10=Textura!$E$3,$B$10=Textura!$F$3,$B$10=Textura!$G$3,$B$10=Textura!$H$3,$B$10=Textura!$L$3),'Rezerva de humus'!$L$3:$U$27,'Rezerva de humus'!$B$3:$K$27),Sheet2!B15,0) -> 1 | V15: =HLOOKUP($B$15,'Conținutul de carbonați'!$B$2:$H$26,Sheet2!B15,0) -> 1
G16: FS (Floarea soarelui) | H16: =PRODUCT(I16:V16) -> 0.9 | I16: =HLOOKUP($B$2,Alunecări!$B$2:$E$26,Sheet2!B16,0) -> 1 | J16: =HLOOKUP($B$3,Panta!$B$2:$F$26,Sheet2!B16,0) -> 1 | K16: =HLOOKUP(MROUND($D$4,0.5),'Temperatura medie anuală'!$B$2:$N$26,Sheet2!B16,TRUE) -> 1 | L16: =HLOOKUP($D$5,IF($D$4<=8,Precipitații!$B$2:$J$26,IF(AND($D$4>8,$D$4<10),Precipitații!$K$2:$S$26,Precipitații!$T$2:$AB$26)),Sheet2!B16,1) -> 1 | M16: =HLOOKUP($B$6,'Salinizarea&Alcalizarea'!$B$2:$F$26,Sheet2!B16,0) -> 1 | N16: =HLOOKUP($B$7,IF('Date Inițiale'!$D$7=Sheet2!$E$3,Gleizarea!$B$2:$I$26,Gleizarea!$J$2:$Q$26),Sheet2!B16,0) -> 1 | O16: =HLOOKUP($B$8,Pseudogleizare!$B$2:$H$26,Sheet2!B16,0) -> 1 | P16: =HLOOKUP($B$9,IF(OR($B$10=Textura!$B$3,$B$10=Textura!$C$3),'Adâncimea apelor freatice'!$C$2:$J$26,IF(OR($B$10=Textura!$D$3,$B$10=Textura!$F$3),'Adâncimea apelor freatice'!$K$2:$R$26,'Adâncimea apelor freatice'!$S$2:$Z$26)),Sheet2!B16,0) -> 1 | Q16: =HLOOKUP($B$10,IF(OR($B$12=Porozitatea!$D$3,Porozitatea!$E$3,Porozitatea!$F$3),Textura!$B$3:$L$27,Textura!$M$3:$W$27),Sheet2!B16,0) -> 1 | R16: =HLOOKUP($B$11,IF($B$5<600,'Volumul edafic util'!$B$3:$G$27,'Volumul edafic util'!$H$3:$M$27),Sheet2!B16,0) -> 1 | S16: =HLOOKUP($B$12,IF(OR($B$10=Textura!$B$3,$B$10=Textura!C16,$B$10=Textura!D16,$B$10=Textura!$E$3,$B$10=Textura!$I$3,$B$10=Textura!$J$3,$B$10=Textura!$K$3),Porozitatea!$B$3:$F$27,Porozitatea!$G$3:$K$27),Sheet2!B16,0) -> 0.9 | T16: =HLOOKUP($B$13,IF($D$13=Sheet2!$F$3,pH!$B$3:$J$27,pH!$K$3:$X$27),Sheet2!B16,0) -> 1 | U16: =HLOOKUP($B$14,IF(OR($B$10=Textura!$D$3,$B$10=Textura!$E$3,$B$10=Textura!$F$3,$B$10=Textura!$G$3,$B$10=Textura!$H$3,$B$10=Textura!$L$3),'Rezerva de humus'!$L$3:$U$27,'Rezerva de humus'!$B$3:$K$27),Sheet2!B16,0) -> 1 | V16: =HLOOKUP($B$15,'Conținutul de carbonați'!$B$2:$H$26,Sheet2!B16,0) -> 1
A17: Cultura | B17: Nota de bonitare | G17: CT (Cartof) | H17: =PRODUCT(I17:V17) -> 0.81 | I17: =HLOOKUP($B$2,Alunecări!$B$2:$E$26,Sheet2!B17,0) -> 1 | J17: =HLOOKUP($B$3,Panta!$B$2:$F$26,Sheet2!B17,0) -> 1 | K17: =HLOOKUP(MROUND($D$4,0.5),'Temperatura medie anuală'!$B$2:$N$26,Sheet2!B17,TRUE) -> 0.9 | L17: =HLOOKUP($D$5,IF($D$4<=8,Precipitații!$B$2:$J$26,IF(AND($D$4>8,$D$4<10),Precipitații!$K$2:$S$26,Precipitații!$T$2:$AB$26)),Sheet2!B17,1) -> 1 | M17: =HLOOKUP($B$6,'Salinizarea&Alcalizarea'!$B$2:$F$26,Sheet2!B17,0) -> 1 | N17: =HLOOKUP($B$7,IF('Date Inițiale'!$D$7=Sheet2!$E$3,Gleizarea!$B$2:$I$26,Gleizarea!$J$2:$Q$26),Sheet2!B17,0) -> 1 | O17: =HLOOKUP($B$8,Pseudogleizare!$B$2:$H$26,Sheet2!B17,0) -> 1 | P17: =HLOOKUP($B$9,IF(OR($B$10=Textura!$B$3,$B$10=Textura!$C$3),'Adâncimea apelor freatice'!$C$2:$J$26,IF(OR($B$10=Textura!$D$3,$B$10=Textura!$F$3),'Adâncimea apelor freatice'!$K$2:$R$26,'Adâncimea apelor freatice'!$S$2:$Z$26)),Sheet2!B17,0) -> 1 | Q17: =HLOOKUP($B$10,IF(OR($B$12=Porozitatea!$D$3,Porozitatea!$E$3,Porozitatea!$F$3),Textura!$B$3:$L$27,Textura!$M$3:$W$27),Sheet2!B17,0) -> 1 | R17: =HLOOKUP($B$11,IF($B$5<600,'Volumul edafic util'!$B$3:$G$27,'Volumul edafic util'!$H$3:$M$27),Sheet2!B17,0) -> 1 | S17: =HLOOKUP($B$12,IF(OR($B$10=Textura!$B$3,$B$10=Textura!C17,$B$10=Textura!D17,$B$10=Textura!$E$3,$B$10=Textura!$I$3,$B$10=Textura!$J$3,$B$10=Textura!$K$3),Porozitatea!$B$3:$F$27,Porozitatea!$G$3:$K$27),Sheet2!B17,0) -> 0.9 | T17: =HLOOKUP($B$13,IF($D$13=Sheet2!$F$3,pH!$B$3:$J$27,pH!$K$3:$X$27),Sheet2!B17,0) -> 1 | U17: =HLOOKUP($B$14,IF(OR($B$10=Textura!$D$3,$B$10=Textura!$E$3,$B$10=Textura!$F$3,$B$10=Textura!$G$3,$B$10=Textura!$H$3,$B$10=Textura!$L$3),'Rezerva de humus'!$L$3:$U$27,'Rezerva de humus'!$B$3:$K$27),Sheet2!B17,0) -> 1 | V17: =HLOOKUP($B$15,'Conținutul de carbonați'!$B$2:$H$26,Sheet2!B17,0) -> 1
A18: =$G$6 -> PR (Păr) | B18: =$H$6 -> 1 | G18: SF (Sfeclă de zahăr) | H18: =PRODUCT(I18:V18) -> 0.8 | I18: =HLOOKUP($B$2,Alunecări!$B$2:$E$26,Sheet2!B18,0) -> 1 | J18: =HLOOKUP($B$3,Panta!$B$2:$F$26,Sheet2!B18,0) -> 1 | K18: =HLOOKUP(MROUND($D$4,0.5),'Temperatura medie anuală'!$B$2:$N$26,Sheet2!B18,TRUE) -> 1 | L18: =HLOOKUP($D$5,IF($D$4<=8,Precipitații!$B$2:$J$26,IF(AND($D$4>8,$D$4<10),Precipitații!$K$2:$S$26,Precipitații!$T$2:$AB$26)),Sheet2!B18,1) -> 1 | M18: =HLOOKUP($B$6,'Salinizarea&Alcalizarea'!$B$2:$F$26,Sheet2!B18,0) -> 1 | N18: =HLOOKUP($B$7,IF('Date Inițiale'!$D$7=Sheet2!$E$3,Gleizarea!$B$2:$I$26,Gleizarea!$J$2:$Q$26),Sheet2!B18,0) -> 1 | O18: =HLOOKUP($B$8,Pseudogleizare!$B$2:$H$26,Sheet2!B18,0) -> 1 | P18: =HLOOKUP($B$9,IF(OR($B$10=Textura!$B$3,$B$10=Textura!$C$3),'Adâncimea apelor freatice'!$C$2:$J$26,IF(OR($B$10=Textura!$D$3,$B$10=Textura!$F$3),'Adâncimea apelor freatice'!$K$2:$R$26,'Adâncimea apelor freatice'!$S$2:$Z$26)),Sheet2!B18,0) -> 1 | Q18: =HLOOKUP($B$10,IF(OR($B$12=Porozitatea!$D$3,Porozitatea!$E$3,Porozitatea!$F$3),Textura!$B$3:$L$27,Textura!$M$3:$W$27),Sheet2!B18,0) -> 1 | R18: =HLOOKUP($B$11,IF($B$5<600,'Volumul edafic util'!$B$3:$G$27,'Volumul edafic util'!$H$3:$M$27),Sheet2!B18,0) -> 1 | S18: =HLOOKUP($B$12,IF(OR($B$10=Textura!$B$3,$B$10=Textura!C18,$B$10=Textura!D18,$B$10=Textura!$E$3,$B$10=Textura!$I$3,$B$10=Textura!$J$3,$B$10=Textura!$K$3),Porozitatea!$B$3:$F$27,Porozitatea!$G$3:$K$27),Sheet2!B18,0) -> 0.8 | T18: =HLOOKUP($B$13,IF($D$13=Sheet2!$F$3,pH!$B$3:$J$27,pH!$K$3:$X$27),Sheet2!B18,0) -> 1 | U18: =HLOOKUP($B$14,IF(OR($B$10=Textura!$D$3,$B$10=Textura!$E$3,$B$10=Textura!$F$3,$B$10=Textura!$G$3,$B$10=Textura!$H$3,$B$10=Textura!$L$3),'Rezerva de humus'!$L$3:$U$27,'Rezerva de humus'!$B$3:$K$27),Sheet2!B18,0) -> 1 | V18: =HLOOKUP($B$15,'Conținutul de carbonați'!$B$2:$H$26,Sheet2!B18,0) -> 1
A19: =$G$7 -> PN (Prun) | B19: =$H$7 -> 1 | G19: SO (Soia) | H19: =PRODUCT(I19:V19) -> 0.9 | I19: =HLOOKUP($B$2,Alunecări!$B$2:$E$26,Sheet2!B19,0) -> 1 | J19: =HLOOKUP($B$3,Panta!$B$2:$F$26,Sheet2!B19,0) -> 1 | K19: =HLOOKUP(MROUND($D$4,0.5),'Temperatura medie anuală'!$B$2:$N$26,Sheet2!B19,TRUE) -> 1 | L19: =HLOOKUP($D$5,IF($D$4<=8,Precipitații!$B$2:$J$26,IF(AND($D$4>8,$D$4<10),Precipitații!$K$2:$S$26,Precipitații!$T$2:$AB$26)),Sheet2!B19,1) -> 1 | M19: =HLOOKUP($B$6,'Salinizarea&Alcalizarea'!$B$2:$F$26,Sheet2!B19,0) -> 1 | N19: =HLOOKUP($B$7,IF('Date Inițiale'!$D$7=Sheet2!$E$3,Gleizarea!$B$2:$I$26,Gleizarea!$J$2:$Q$26),Sheet2!B19,0) -> 1 | O19: =HLOOKUP($B$8,Pseudogleizare!$B$2:$H$26,Sheet2!B19,0) -> 1 | P19: =HLOOKUP($B$9,IF(OR($B$10=Textura!$B$3,$B$10=Textura!$C$3),'Adâncimea apelor freatice'!$C$2:$J$26,IF(OR($B$10=Textura!$D$3,$B$10=Textura!$F$3),'Adâncimea apelor freatice'!$K$2:$R$26,'Adâncimea apelor freatice'!$S$2:$Z$26)),Sheet2!B19,0) -> 1 | Q19: =HLOOKUP($B$10,IF(OR($B$12=Porozitatea!$D$3,Porozitatea!$E$3,Porozitatea!$F$3),Textura!$B$3:$L$27,Textura!$M$3:$W$27),Sheet2!B19,0) -> 1 | R19: =HLOOKUP($B$11,IF($B$5<600,'Volumul edafic util'!$B$3:$G$27,'Volumul edafic util'!$H$3:$M$27),Sheet2!B19,0) -> 1 | S19: =HLOOKUP($B$12,IF(OR($B$10=Textura!$B$3,$B$10=Textura!C19,$B$10=Textura!D19,$B$10=Textura!$E$3,$B$10=Textura!$I$3,$B$10=Textura!$J$3,$B$10=Textura!$K$3),Porozitatea!$B$3:$F$27,Porozitatea!$G$3:$K$27),Sheet2!B19,0) -> 0.9 | T19: =HLOOKUP($B$13,IF($D$13=Sheet2!$F$3,pH!$B$3:$J$27,pH!$K$3:$X$27),Sheet2!B19,0) -> 1 | U19: =HLOOKUP($B$14,IF(OR($B$10=Textura!$D$3,$B$10=Textura!$E$3,$B$10=Textura!$F$3,$B$10=Textura!$G$3,$B$10=Textura!$H$3,$B$10=Textura!$L$3),'Rezerva de humus'!$L$3:$U$27,'Rezerva de humus'!$B$3:$K$27),Sheet2!B19,0) -> 1 | V19: =HLOOKUP($B$15,'Conținutul de carbonați'!$B$2:$H$26,Sheet2!B19,0) -> 1
A20: =$G$8 -> CV (Cireș) | B20: =$H$8 -> 1 | G20: MF (Mazăre-fasole) | H20: =PRODUCT(I20:V20) -> 1 | I20: =HLOOKUP($B$2,Alunecări!$B$2:$E$26,Sheet2!B20,0) -> 1 | J20: =HLOOKUP($B$3,Panta!$B$2:$F$26,Sheet2!B20,0) -> 1 | K20: =HLOOKUP(MROUND($D$4,0.5),'Temperatura medie anuală'!$B$2:$N$26,Sheet2!B20,TRUE) -> 1 | L20: =HLOOKUP($D$5,IF($D$4<=8,Precipitații!$B$2:$J$26,IF(AND($D$4>8,$D$4<10),Precipitații!$K$2:$S$26,Precipitații!$T$2:$AB$26)),Sheet2!B20,1) -> 1 | M20: =HLOOKUP($B$6,'Salinizarea&Alcalizarea'!$B$2:$F$26,Sheet2!B20,0) -> 1 | N20: =HLOOKUP($B$7,IF('Date Inițiale'!$D$7=Sheet2!$E$3,Gleizarea!$B$2:$I$26,Gleizarea!$J$2:$Q$26),Sheet2!B20,0) -> 1 | O20: =HLOOKUP($B$8,Pseudogleizare!$B$2:$H$26,Sheet2!B20,0) -> 1 | P20: =HLOOKUP($B$9,IF(OR($B$10=Textura!$B$3,$B$10=Textura!$C$3),'Adâncimea apelor freatice'!$C$2:$J$26,IF(OR($B$10=Textura!$D$3,$B$10=Textura!$F$3),'Adâncimea apelor freatice'!$K$2:$R$26,'Adâncimea apelor freatice'!$S$2:$Z$26)),Sheet2!B20,0) -> 1 | Q20: =HLOOKUP($B$10,IF(OR($B$12=Porozitatea!$D$3,Porozitatea!$E$3,Porozitatea!$F$3),Textura!$B$3:$L$27,Textura!$M$3:$W$27),Sheet2!B20,0) -> 1 | R20: =HLOOKUP($B$11,IF($B$5<600,'Volumul edafic util'!$B$3:$G$27,'Volumul edafic util'!$H$3:$M$27),Sheet2!B20,0) -> 1 | S20: =HLOOKUP($B$12,IF(OR($B$10=Textura!$B$3,$B$10=Textura!C20,$B$10=Textura!D20,$B$10=Textura!$E$3,$B$10=Textura!$I$3,$B$10=Textura!$J$3,$B$10=Textura!$K$3),Porozitatea!$B$3:$F$27,Porozitatea!$G$3:$K$27),Sheet2!B20,0) -> 1 | T20: =HLOOKUP($B$13,IF($D$13=Sheet2!$F$3,pH!$B$3:$J$27,pH!$K$3:$X$27),Sheet2!B20,0) -> 1 | U20: =HLOOKUP($B$14,IF(OR($B$10=Textura!$D$3,$B$10=Textura!$E$3,$B$10=Textura!$F$3,$B$10=Textura!$G$3,$B$10=Textura!$H$3,$B$10=Textura!$L$3),'Rezerva de humus'!$L$3:$U$27,'Rezerva de humus'!$B$3:$K$27),Sheet2!B20,0) -> 1 | V20: =HLOOKUP($B$15,'Conținutul de carbonați'!$B$2:$H$26,Sheet2!B20,0) -> 1
A21: =$G$9 -> CS (Cais) | B21: =$H$9 -> 1 | G21: IU (In ulei) | H21: =PRODUCT(I21:V21) -> 1 | I21: =HLOOKUP($B$2,Alunecări!$B$2:$E$26,Sheet2!B21,0) -> 1 | J21: =HLOOKUP($B$3,Panta!$B$2:$F$26,Sheet2!B21,0) -> 1 | K21: =HLOOKUP(MROUND($D$4,0.5),'Temperatura medie anuală'!$B$2:$N$26,Sheet2!B21,TRUE) -> 1 | L21: =HLOOKUP($D$5,IF($D$4<=8,Precipitații!$B$2:$J$26,IF(AND($D$4>8,$D$4<10),Precipitații!$K$2:$S$26,Precipitații!$T$2:$AB$26)),Sheet2!B21,1) -> 1 | M21: =HLOOKUP($B$6,'Salinizarea&Alcalizarea'!$B$2:$F$26,Sheet2!B21,0) -> 1 | N21: =HLOOKUP($B$7,IF('Date Inițiale'!$D$7=Sheet2!$E$3,Gleizarea!$B$2:$I$26,Gleizarea!$J$2:$Q$26),Sheet2!B21,0) -> 1 | O21: =HLOOKUP($B$8,Pseudogleizare!$B$2:$H$26,Sheet2!B21,0) -> 1 | P21: =HLOOKUP($B$9,IF(OR($B$10=Textura!$B$3,$B$10=Textura!$C$3),'Adâncimea apelor freatice'!$C$2:$J$26,IF(OR($B$10=Textura!$D$3,$B$10=Textura!$F$3),'Adâncimea apelor freatice'!$K$2:$R$26,'Adâncimea apelor freatice'!$S$2:$Z$26)),Sheet2!B21,0) -> 1 | Q21: =HLOOKUP($B$10,IF(OR($B$12=Porozitatea!$D$3,Porozitatea!$E$3,Porozitatea!$F$3),Textura!$B$3:$L$27,Textura!$M$3:$W$27),Sheet2!B21,0) -> 1 | R21: =HLOOKUP($B$11,IF($B$5<600,'Volumul edafic util'!$B$3:$G$27,'Volumul edafic util'!$H$3:$M$27),Sheet2!B21,0) -> 1 | S21: =HLOOKUP($B$12,IF(OR($B$10=Textura!$B$3,$B$10=Textura!C21,$B$10=Textura!D21,$B$10=Textura!$E$3,$B$10=Textura!$I$3,$B$10=Textura!$J$3,$B$10=Textura!$K$3),Porozitatea!$B$3:$F$27,Porozitatea!$G$3:$K$27),Sheet2!B21,0) -> 1 | T21: =HLOOKUP($B$13,IF($D$13=Sheet2!$F$3,pH!$B$3:$J$27,pH!$K$3:$X$27),Sheet2!B21,0) -> 1 | U21: =HLOOKUP($B$14,IF(OR($B$10=Textura!$D$3,$B$10=Textura!$E$3,$B$10=Textura!$F$3,$B$10=Textura!$G$3,$B$10=Textura!$H$3,$B$10=Textura!$L$3),'Rezerva de humus'!$L$3:$U$27,'Rezerva de humus'!$B$3:$K$27),Sheet2!B21,0) -> 1 | V21: =HLOOKUP($B$15,'Conținutul de carbonați'!$B$2:$H$26,Sheet2!B21,0) -> 1
A22: =$G$10 -> PC (Piersic) | B22: =$H$10 -> 1 | G22: IF (In fibre) | H22: =PRODUCT(I22:V22) -> 0.9 | I22: =HLOOKUP($B$2,Alunecări!$B$2:$E$26,Sheet2!B22,0) -> 1 | J22: =HLOOKUP($B$3,Panta!$B$2:$F$26,Sheet2!B22,0) -> 1 | K22: =HLOOKUP(MROUND($D$4,0.5),'Temperatura medie anuală'!$B$2:$N$26,Sheet2!B22,TRUE) -> 0.9 | L22: =HLOOKUP($D$5,IF($D$4<=8,Precipitații!$B$2:$J$26,IF(AND($D$4>8,$D$4<10),Precipitații!$K$2:$S$26,Precipitații!$T$2:$AB$26)),Sheet2!B22,1) -> 1 | M22: =HLOOKUP($B$6,'Salinizarea&Alcalizarea'!$B$2:$F$26,Sheet2!B22,0) -> 1 | N22: =HLOOKUP($B$7,IF('Date Inițiale'!$D$7=Sheet2!$E$3,Gleizarea!$B$2:$I$26,Gleizarea!$J$2:$Q$26),Sheet2!B22,0) -> 1 | O22: =HLOOKUP($B$8,Pseudogleizare!$B$2:$H$26,Sheet2!B22,0) -> 1 | P22: =HLOOKUP($B$9,IF(OR($B$10=Textura!$B$3,$B$10=Textura!$C$3),'Adâncimea apelor freatice'!$C$2:$J$26,IF(OR($B$10=Textura!$D$3,$B$10=Textura!$F$3),'Adâncimea apelor freatice'!$K$2:$R$26,'Adâncimea apelor freatice'!$S$2:$Z$26)),Sheet2!B22,0) -> 1 | Q22: =HLOOKUP($B$10,IF(OR($B$12=Porozitatea!$D$3,Porozitatea!$E$3,Porozitatea!$F$3),Textura!$B$3:$L$27,Textura!$M$3:$W$27),Sheet2!B22,0) -> 1 | R22: =HLOOKUP($B$11,IF($B$5<600,'Volumul edafic util'!$B$3:$G$27,'Volumul edafic util'!$H$3:$M$27),Sheet2!B22,0) -> 1 | S22: =HLOOKUP($B$12,IF(OR($B$10=Textura!$B$3,$B$10=Textura!C22,$B$10=Textura!D22,$B$10=Textura!$E$3,$B$10=Textura!$I$3,$B$10=Textura!$J$3,$B$10=Textura!$K$3),Porozitatea!$B$3:$F$27,Porozitatea!$G$3:$K$27),Sheet2!B22,0) -> 1 | T22: =HLOOKUP($B$13,IF($D$13=Sheet2!$F$3,pH!$B$3:$J$27,pH!$K$3:$X$27),Sheet2!B22,0) -> 1 | U22: =HLOOKUP($B$14,IF(OR($B$10=Textura!$D$3,$B$10=Textura!$E$3,$B$10=Textura!$F$3,$B$10=Textura!$G$3,$B$10=Textura!$H$3,$B$10=Textura!$L$3),'Rezerva de humus'!$L$3:$U$27,'Rezerva de humus'!$B$3:$K$27),Sheet2!B22,0) -> 1 | V22: =HLOOKUP($B$15,'Conținutul de carbonați'!$B$2:$H$26,Sheet2!B22,0) -> 1
A23: =$G$11 -> VV (Vie-vin) | B23: =$H$11 -> 1 | G23: CN (Cânepă) | H23: =PRODUCT(I23:V23) -> 1 | I23: =HLOOKUP($B$2,Alunecări!$B$2:$E$26,Sheet2!B23,0) -> 1 | J23: =HLOOKUP($B$3,Panta!$B$2:$F$26,Sheet2!B23,0) -> 1 | K23: =HLOOKUP(MROUND($D$4,0.5),'Temperatura medie anuală'!$B$2:$N$26,Sheet2!B23,TRUE) -> 1 | L23: =HLOOKUP($D$5,IF($D$4<=8,Precipitații!$B$2:$J$26,IF(AND($D$4>8,$D$4<10),Precipitații!$K$2:$S$26,Precipitații!$T$2:$AB$26)),Sheet2!B23,1) -> 1 | M23: =HLOOKUP($B$6,'Salinizarea&Alcalizarea'!$B$2:$F$26,Sheet2!B23,0) -> 1 | N23: =HLOOKUP($B$7,IF('Date Inițiale'!$D$7=Sheet2!$E$3,Gleizarea!$B$2:$I$26,Gleizarea!$J$2:$Q$26),Sheet2!B23,0) -> 1 | O23: =HLOOKUP($B$8,Pseudogleizare!$B$2:$H$26,Sheet2!B23,0) -> 1 | P23: =HLOOKUP($B$9,IF(OR($B$10=Textura!$B$3,$B$10=Textura!$C$3),'Adâncimea apelor freatice'!$C$2:$J$26,IF(OR($B$10=Textura!$D$3,$B$10=Textura!$F$3),'Adâncimea apelor freatice'!$K$2:$R$26,'Adâncimea apelor freatice'!$S$2:$Z$26)),Sheet2!B23,0) -> 1 | Q23: =HLOOKUP($B$10,IF(OR($B$12=Porozitatea!$D$3,Porozitatea!$E$3,Porozitatea!$F$3),Textura!$B$3:$L$27,Textura!$M$3:$W$27),Sheet2!B23,0) -> 1 | R23: =HLOOKUP($B$11,IF($B$5<600,'Volumul edafic util'!$B$3:$G$27,'Volumul edafic util'!$H$3:$M$27),Sheet2!B23,0) -> 1 | S23: =HLOOKUP($B$12,IF(OR($B$10=Textura!$B$3,$B$10=Textura!C23,$B$10=Textura!D23,$B$10=Textura!$E$3,$B$10=Textura!$I$3,$B$10=Textura!$J$3,$B$10=Textura!$K$3),Porozitatea!$B$3:$F$27,Porozitatea!$G$3:$K$27),Sheet2!B23,0) -> 1 | T23: =HLOOKUP($B$13,IF($D$13=Sheet2!$F$3,pH!$B$3:$J$27,pH!$K$3:$X$27),Sheet2!B23,0) -> 1 | U23: =HLOOKUP($B$14,IF(OR($B$10=Textura!$D$3,$B$10=Textura!$E$3,$B$10=Textura!$F$3,$B$10=Textura!$G$3,$B$10=Textura!$H$3,$B$10=Textura!$L$3),'Rezerva de humus'!$L$3:$U$27,'Rezerva de humus'!$B$3:$K$27),Sheet2!B23,0) -> 1 | V23: =HLOOKUP($B$15,'Conținutul de carbonați'!$B$2:$H$26,Sheet2!B23,0) -> 1
A24: =$G$12 -> VM (Vie-masă) | B24: =$H$12 -> 1 | G24: LU (Lucernă) | H24: =PRODUCT(I24:V24) -> 1 | I24: =HLOOKUP($B$2,Alunecări!$B$2:$E$26,Sheet2!B24,0) -> 1 | J24: =HLOOKUP($B$3,Panta!$B$2:$F$26,Sheet2!B24,0) -> 1 | K24: =HLOOKUP(MROUND($D$4,0.5),'Temperatura medie anuală'!$B$2:$N$26,Sheet2!B24,TRUE) -> 1 | L24: =HLOOKUP($D$5,IF($D$4<=8,Precipitații!$B$2:$J$26,IF(AND($D$4>8,$D$4<10),Precipitații!$K$2:$S$26,Precipitații!$T$2:$AB$26)),Sheet2!B24,1) -> 1 | M24: =HLOOKUP($B$6,'Salinizarea&Alcalizarea'!$B$2:$F$26,Sheet2!B24,0) -> 1 | N24: =HLOOKUP($B$7,IF('Date Inițiale'!$D$7=Sheet2!$E$3,Gleizarea!$B$2:$I$26,Gleizarea!$J$2:$Q$26),Sheet2!B24,0) -> 1 | O24: =HLOOKUP($B$8,Pseudogleizare!$B$2:$H$26,Sheet2!B24,0) -> 1 | P24: =HLOOKUP($B$9,IF(OR($B$10=Textura!$B$3,$B$10=Textura!$C$3),'Adâncimea apelor freatice'!$C$2:$J$26,IF(OR($B$10=Textura!$D$3,$B$10=Textura!$F$3),'Adâncimea apelor freatice'!$K$2:$R$26,'Adâncimea apelor freatice'!$S$2:$Z$26)),Sheet2!B24,0) -> 1 | Q24: =HLOOKUP($B$10,IF(OR($B$12=Porozitatea!$D$3,Porozitatea!$E$3,Porozitatea!$F$3),Textura!$B$3:$L$27,Textura!$M$3:$W$27),Sheet2!B24,0) -> 1 | R24: =HLOOKUP($B$11,IF($B$5<600,'Volumul edafic util'!$B$3:$G$27,'Volumul edafic util'!$H$3:$M$27),Sheet2!B24,0) -> 1 | S24: =HLOOKUP($B$12,IF(OR($B$10=Textura!$B$3,$B$10=Textura!C24,$B$10=Textura!D24,$B$10=Textura!$E$3,$B$10=Textura!$I$3,$B$10=Textura!$J$3,$B$10=Textura!$K$3),Porozitatea!$B$3:$F$27,Porozitatea!$G$3:$K$27),Sheet2!B24,0) -> 1 | T24: =HLOOKUP($B$13,IF($D$13=Sheet2!$F$3,pH!$B$3:$J$27,pH!$K$3:$X$27),Sheet2!B24,0) -> 1 | U24: =HLOOKUP($B$14,IF(OR($B$10=Textura!$D$3,$B$10=Textura!$E$3,$B$10=Textura!$F$3,$B$10=Textura!$G$3,$B$10=Textura!$H$3,$B$10=Textura!$L$3),'Rezerva de humus'!$L$3:$U$27,'Rezerva de humus'!$B$3:$K$27),Sheet2!B24,0) -> 1 | V24: =HLOOKUP($B$15,'Conținutul de carbonați'!$B$2:$H$26,Sheet2!B24,0) -> 1
A25: =$G$20 -> MF (Mazăre-fasole) | B25: =$H$20 -> 1 | G25: TR (Trifoi) | H25: =PRODUCT(I25:V25) -> 0.648 | I25: =HLOOKUP($B$2,Alunecări!$B$2:$E$26,Sheet2!B25,0) -> 1 | J25: =HLOOKUP($B$3,Panta!$B$2:$F$26,Sheet2!B25,0) -> 1 | K25: =HLOOKUP(MROUND($D$4,0.5),'Temperatura medie anuală'!$B$2:$N$26,Sheet2!B25,TRUE) -> 0.8 | L25: =HLOOKUP($D$5,IF($D$4<=8,Precipitații!$B$2:$J$26,IF(AND($D$4>8,$D$4<10),Precipitații!$K$2:$S$26,Precipitații!$T$2:$AB$26)),Sheet2!B25,1) -> 1 | M25: =HLOOKUP($B$6,'Salinizarea&Alcalizarea'!$B$2:$F$26,Sheet2!B25,0) -> 1 | N25: =HLOOKUP($B$7,IF('Date Inițiale'!$D$7=Sheet2!$E$3,Gleizarea!$B$2:$I$26,Gleizarea!$J$2:$Q$26),Sheet2!B25,0) -> 1 | O25: =HLOOKUP($B$8,Pseudogleizare!$B$2:$H$26,Sheet2!B25,0) -> 1 | P25: =HLOOKUP($B$9,IF(OR($B$10=Textura!$B$3,$B$10=Textura!$C$3),'Adâncimea apelor freatice'!$C$2:$J$26,IF(OR($B$10=Textura!$D$3,$B$10=Textura!$F$3),'Adâncimea apelor freatice'!$K$2:$R$26,'Adâncimea apelor freatice'!$S$2:$Z$26)),Sheet2!B25,0) -> 0.9 | Q25: =HLOOKUP($B$10,IF(OR($B$12=Porozitatea!$D$3,Porozitatea!$E$3,Porozitatea!$F$3),Textura!$B$3:$L$27,Textura!$M$3:$W$27),Sheet2!B25,0) -> 1 | R25: =HLOOKUP($B$11,IF($B$5<600,'Volumul edafic util'!$B$3:$G$27,'Volumul edafic util'!$H$3:$M$27),Sheet2!B25,0) -> 1 | S25: =HLOOKUP($B$12,IF(OR($B$10=Textura!$B$3,$B$10=Textura!C25,$B$10=Textura!D25,$B$10=Textura!$E$3,$B$10=Textura!$I$3,$B$10=Textura!$J$3,$B$10=Textura!$K$3),Porozitatea!$B$3:$F$27,Porozitatea!$G$3:$K$27),Sheet2!B25,0) -> 0.9 | T25: =HLOOKUP($B$13,IF($D$13=Sheet2!$F$3,pH!$B$3:$J$27,pH!$K$3:$X$27),Sheet2!B25,0) -> 1 | U25: =HLOOKUP($B$14,IF(OR($B$10=Textura!$D$3,$B$10=Textura!$E$3,$B$10=Textura!$F$3,$B$10=Textura!$G$3,$B$10=Textura!$H$3,$B$10=Textura!$L$3),'Rezerva de humus'!$L$3:$U$27,'Rezerva de humus'!$B$3:$K$27),Sheet2!B25,0) -> 1 | V25: =HLOOKUP($B$15,'Conținutul de carbonați'!$B$2:$H$26,Sheet2!B25,0) -> 1
A26: =$G$21 -> IU (In ulei) | B26: =$H$21 -> 1 | G26: LG (Legume) | H26: =PRODUCT(I26:V26) -> 0.9 | I26: =HLOOKUP($B$2,Alunecări!$B$2:$E$26,Sheet2!B26,0) -> 1 | J26: =HLOOKUP($B$3,Panta!$B$2:$F$26,Sheet2!B26,0) -> 1 | K26: =HLOOKUP(MROUND($D$4,0.5),'Temperatura medie anuală'!$B$2:$N$26,Sheet2!B26,TRUE) -> 1 | L26: =HLOOKUP($D$5,IF($D$4<=8,Precipitații!$B$2:$J$26,IF(AND($D$4>8,$D$4<10),Precipitații!$K$2:$S$26,Precipitații!$T$2:$AB$26)),Sheet2!B26,1) -> 1 | M26: =HLOOKUP($B$6,'Salinizarea&Alcalizarea'!$B$2:$F$26,Sheet2!B26,0) -> 1 | N26: =HLOOKUP($B$7,IF('Date Inițiale'!$D$7=Sheet2!$E$3,Gleizarea!$B$2:$I$26,Gleizarea!$J$2:$Q$26),Sheet2!B26,0) -> 1 | O26: =HLOOKUP($B$8,Pseudogleizare!$B$2:$H$26,Sheet2!B26,0) -> 1 | P26: =HLOOKUP($B$9,IF(OR($B$10=Textura!$B$3,$B$10=Textura!$C$3),'Adâncimea apelor freatice'!$C$2:$J$26,IF(OR($B$10=Textura!$D$3,$B$10=Textura!$F$3),'Adâncimea apelor freatice'!$K$2:$R$26,'Adâncimea apelor freatice'!$S$2:$Z$26)),Sheet2!B26,0) -> 0.9 | Q26: =HLOOKUP($B$10,IF(OR($B$12=Porozitatea!$D$3,Porozitatea!$E$3,Porozitatea!$F$3),Textura!$B$3:$L$27,Textura!$M$3:$W$27),Sheet2!B26,0) -> 1 | R26: =HLOOKUP($B$11,IF($B$5<600,'Volumul edafic util'!$B$3:$G$27,'Volumul edafic util'!$H$3:$M$27),Sheet2!B26,0) -> 1 | S26: =HLOOKUP($B$12,IF(OR($B$10=Textura!$B$3,$B$10=Textura!C26,$B$10=Textura!D26,$B$10=Textura!$E$3,$B$10=Textura!$I$3,$B$10=Textura!$J$3,$B$10=Textura!$K$3),Porozitatea!$B$3:$F$27,Porozitatea!$G$3:$K$27),Sheet2!B26,0) -> 1 | T26: =HLOOKUP($B$13,IF($D$13=Sheet2!$F$3,pH!$B$3:$J$27,pH!$K$3:$X$27),Sheet2!B26,0) -> 1 | U26: =HLOOKUP($B$14,IF(OR($B$10=Textura!$D$3,$B$10=Textura!$E$3,$B$10=Textura!$F$3,$B$10=Textura!$G$3,$B$10=Textura!$H$3,$B$10=Textura!$L$3),'Rezerva de humus'!$L$3:$U$27,'Rezerva de humus'!$B$3:$K$27),Sheet2!B26,0) -> 1 | V26: =HLOOKUP($B$15,'Conținutul de carbonați'!$B$2:$H$26,Sheet2!B26,0) -> 1
A27: =$G$23 -> CN (Cânepă) | B27: =$H$23 -> 1
A28: =$G$24 -> LU (Lucernă) | B28: =$H$24 -> 1
A29: =$G$5 -> MR (Măr) | B29: =$H$5 -> 0.9
A30: =$G$14 -> OR (Orz) | B30: =$H$14 -> 0.9
A31: =$G$15 -> PB (Porumb) | B31: =$H$15 -> 0.9
A32: =$G$16 -> FS (Floarea soarelui) | B32: =$H$16 -> 0.9
A33: =$G$19 -> SO (Soia) | B33: =$H$19 -> 0.9
A34: =$G$22 -> IF (In fibre) | B34: =$H$22 -> 0.9
A35: =$G$26 -> LG (Legume) | B35: =$H$26 -> 0.9
A36: =$G$3 -> PS (Pășuni) | B36: =$H$3 -> 0.81
A37: =$G$17 -> CT (Cartof) | B37: =$H$17 -> 0.81
A38: =$G$13 -> GR (Grâu) | B38: =$H$13 -> 0.8
A39: =$G$18 -> SF (Sfeclă de zahăr) | B39: =$H$18 -> 0.8
A40: =$G$4 -> FN (Fânețe) | B40: =$H$4 -> 0.648
...

Sheet Alunecări
A1: Cultura | B1: Caracterul alunecărilor de teren
B2: Absente | C2: Stabilizate | D2: Semistabilizate | E2: Active
A3: PS (Pășuni) | B3: 1 | C3: 0.9 | D3: 0.8 | E3: 0.7
A4: FN (Fânețe) | B4: 1 | C4: 0.9 | D4: 0.8 | E4: 0.7
A5: MR (Măr) | B5: 1 | C5: 0.7 | D5: 0.6 | E5: 0.4
A6: PR (Păr) | B6: 1 | C6: 0.6 | D6: 0.5 | E6: 0.3
A7: PN (Prun) | B7: 1 | C7: 0.8 | D7: 0.7 | E7: 0.5
A8: CV (Cireș) | B8: 1 | C8: 0.8 | D8: 0.6 | E8: 0.4
A9: CS (Cais) | B9: 1 | C9: 0.6 | D9: 0.5 | E9: 0.4
A10: PC (Piersic) | B10: 1 | C10: 0.6 | D10: 0.5 | E10: 0.3
A11: VV (Vie-vin) | B11: 1 | C11: 0.6 | D11: 0.5 | E11: 0.3
A12: VM (Vie-masă) | B12: 1 | C12: 0.5 | D12: 0.4 | E12: 0.2
A13: GR (Grâu) | B13: 1 | C13: 0.8 | D13: 0.7 | E13: 0.6
A14: OR (Orz) | B14: 1 | C14: 0.8 | D14: 0.7 | E14: 0.6
... A26: LG (Legume) | B26: 1 | C26: 0.6 | D26: 0.5 | E26: 0.4

Sheet Panta
A1: Cultura | B1: Panta
B2: P≤5% | C2: 5%<P≤10% | D2: 10%<P≤15% | E2: 15%<P≤20% | F2: 20%<P≤25%
A3: PS (Pășuni) | B3: 1 | C3: 1 | D3: 1 | E3: 0.9 | F3: 0.8
A4: FN (Fânețe) | B4: 1 | C4: 1 | D4: 0.9 | E4: 0.8 | F4: 0.7
A5: MR (Măr) | B5: 1 | C5: 1 | D5: 0.9 | E5: 0.8 | F5: 0.7
A6: PR (Păr) | B6: 1 | C6: 1 | D6: 0.9 | E6: 0.8 | F6: 0.6
A7: PN (Prun) | B7: 1 | C7: 1 | D7: 1 | E7: 0.9 | F7: 0.8
A8: CV (Cireș) | B8: 1 | C8: 1 | D8: 0.9 | E8: 0.8 | F8: 0.7
A9: CS (Cais) | B9: 1 | C9: 1 | D9: 0.9 | E9: 0.7 | F9: 0.4
A10: PC (Piersic) | B10: 1 | C10: 1 | D10: 0.8 | E10: 0.6 | F10: 0.3
A11: VV (Vie-vin) | B11: 1 | C11: 1 | D11: 0.9 | E11: 0.8 | F11: 0.7
A12: VM (Vie-masă) | B12: 1 | C12: 0.9 | D12: 0.8 | E12: 0.6 | F12: 0.5
A13: GR (Grâu) | B13: 1 | C13: 1 | D13: 0.9 | E13: 0.8 | F13: 0.6
A14: OR (Orz) | B14: 1 | C14: 1 | D14: 0.9 | E14: 0.8 | F14: 0.6
... A26: LG (Legume) | B26: 1 | C26: 0.9 | D26: 0.7 | E26: 0.5 | F26: 0.3

Sheet Temperatura medie anuală
A1: Cultura | B1: Media anuală a temperaturii aerului | P1: Temperatura | R1: -3 | S1: -1 | T1: 1 | U1: 3 | V1: 4.5 | W1: 5.5 | X1: 6.5 | Y1: 7.5 | Z1: 8.5 | AA1: 9.5 | AB1: 10.5 | AC1: 11.5
B2: -3 | C2: -1 | D2: 1 | E2: 3 | F2: 4.5 | G2: 5.5 | H2: 6.5 | I2: 7.5 | J2: 8.5 | K2: 9.5 | L2: 10.5 | M2: 11.5 | N2: 12.5 | P2: 10%<P≤15% | Q2: N | R2: -3 | S2: -1 | T2: 1 | U2: 3 | V2: 4.5 | W2: 5.5 | X2: 6.5 | Y2: 7.5 | Z2: 8.5 | AA2: 9.5 | AB2: 10.5 | AC2: 11.5
A3: PS (Pășuni) | B3: 0.3 | C3: 0.5 | D3: 0.6 | E3: 0.8 | F3: 0.9 | G3: 0.9 | H3: 1 | I3: 1 | J3: 1 | K3: 1 | L3: 1 | M3: 1 | N3: 0.9 | Q3: E | R3: -3 | S3: -1 | T3: 1 | U3: 3 | V3: 4.5 | W3: 5.5 | X3: 6.5 | Y3: 7.5 | Z3: 8.5 | AA3: 9.5 | AB3: 10.5 | AC3: 11.5
A4: FN (Fânețe) | B4: 0.2 | C4: 0.3 | D4: 0.4 | E4: 0.6 | F4: 0.8 | G4: 0.9 | H4: 1 | I4: 1 | J4: 1 | K4: 1 | L4: 1 | M4: 1 | N4: 0.9 | Q4: S | R4: -3 | S4: -1 | T4: 1 | U4: 3 | V4: 4.5 | W4: 5.5 | X4: 6.5 | Y4: 7.5 | Z4: 8.5 | AA4: 10.5 | AB4: 11.5 | AC4: 12.5
A5: MR (Măr) | B5: 0 | C5: 0 | D5: 0 | E5: 0.2 | F5: 0.3 | G5: 0.5 | H5: 0.6 | I5: 0.9 | J5: 0.9 | K5: 1 | L5: 1 | M5: 0.9 | N5: 0.8 | Q5: V | R5: -3 | S5: -1 | T5: 1 | U5: 3 | V5: 4.5 | W5: 5.5 | X5: 6.5 | Y5: 7.5 | Z5: 8.5 | AA5: 9.5 | AB5: 10.5 | AC5: 11.5
A6: PR (Păr) | B6: 0 | C6: 0 | D6: 0 | E6: 0 | F6: 0.1 | G6: 0.3 | H6: 0.5 | I6: 0.8 | J6: 0.9 | K6: 1 | L6: 1 | M6: 0.8 | N6: 0.7 | P6: 15%<P≤20% | Q6: N | R6: -3 | S6: -1 | T6: 1 | U6: 3 | V6: 4.5 | W6: 5.5 | X6: 6.5 | Y6: 6.5 | Z6: 7.5 | AA6: 8.5 | AB6: 9.5 | AC6: 10.5
A7: PN (Prun) | B7: 0 | C7: 0 | D7: 0 | E7: 0 | F7: 0.1 | G7: 0.3 | H7: 0.5 | I7: 0.8 | J7: 0.9 | K7: 1 | L7: 1 | M7: 0.8 | N7: 0.7 | Q7: E | R7: -3 | S7: -1 | T7: 1 | U7: 3 | V7: 4.5 | W7: 5.5 | X7: 6.5 | Y7: 7.5 | Z7: 8.5 | AA7: 9.5 | AB7: 10.5 | AC7: 11.5
A8: CV (Cireș) | B8: 0 | C8: 0 | D8: 0 | E8: 0 | F8: 0.1 | G8: 0.3 | H8: 0.5 | I8: 0.8 | J8: 1 | K8: 1 | L8: 1 | M8: 0.9 | N8: 0.8 | Q8: S | R8: -3 | S8: -1 | T8: 1 | U8: 3 | V8: 4.5 | W8: 6.5 | X8: 7.5 | Y8: 8.5 | Z8: 9.5 | AA8: 10.5 | AB8: 11.5 | AC8: 12.5
A9: CS (Cais) | B9: 0 | C9: 0 | D9: 0 | E9: 0 | F9: 0 | G9: 0 | H9: 0.1 | I9: 0.4 | J9: 0.7 | K9: 1 | L9: 1 | M9: 1 | N9: 1 | Q9: V | R9: -3 | S9: -1 | T9: 1 | U9: 3 | V9: 4.5 | W9: 5.5 | X9: 6.5 | Y9: 7.5 | Z9: 9.5 | AA9: 10.5 | AB9: 11.5 | AC9: 12.5
A10: PC (Piersic) | B10: 0 | C10: 0 | D10: 0 | E10: 0 | F10: 0 | G10: 0.1 | H10: 0.2 | I10: 0.4 | J10: 0.6 | K10: 0.9 | L10: 1 | M10: 1 | N10: 1 | P10: 20%<P≤25% | Q10: N | R10: -3 | S10: -3 | T10: -1 | U10: 1 | V10: 3 | W10: 4.5 | X10: 5.5 | Y10: 6.5 | Z10: 7.5 | AA10: 8.5 | AB10: 9.5 | AC10: 10.5
A11: VV (Vie-vin) | B11: 0 | C11: 0 | D11: 0 | E11: 0 | F11: 0 | G11: 0 | H11: 0.1 | I11: 0.2 | J11: 0.8 | K11: 1 | L11: 1 | M11: 1 | N11: 0.9
A12: VM (Vie-masă) | B12: 0 | C12: 0 | D12: 0 | E12: 0 | F12: 0 | G12: 0 | H12: 0.1 | I12: 0.1 | J12: 0.3 | K12: 0.8 | L12: 1 | M12: 1 | N12: 1
A13: GR (Grâu) | B13: 0 | C13: 0 | D13: 0.1 | E13: 0.2 | F13: 0.5 | G13: 0.7 | H13: 0.8 | I13: 0.9 | J13: 1 | K13: 1 | L13: 1 | M13: 1 | N13: 0.9
A14: OR (Orz) | B14: 0 | C14: 0 | D14: 0 | E14: 0.1 | F14: 0.5 | G14: 0.7 | H14: 0.8 | I14: 0.9 | J14: 1 | K14: 1 | L14: 1 | M14: 1 | N14: 1
A15: PB (Porumb) | B15: 0 | C15: 0 | D15: 0 | E15: 0.1 | F15: 0.1 | G15: 0.3 | H15: 0.5 | I15: 0.8 | J15: 0.9 | K15: 0.9 | L15: 1 | M15: 1 | N15: 1
A16: FS (Floarea soarelui) | B16: 0 | C16: 0 | D16: 0 | E16: 0 | F16: 0.1 | G16: 0.2 | H16: 0.3 | I16: 0.5 | J16: 0.9 | K16: 0.9 | L16: 1 | M16: 1 | N16: 1
A17: CT (Cartof) | B17: 0 | C17: 0.1 | D17: 0.1 | E17: 0.2 | F17: 0.6 | G17: 0.7 | H17: 0.9 | I17: 1 | J17: 1 | K17: 0.9 | L17: 0.9 | M17: 0.8 | N17: 0.7 | R17: =ABS(R18-'Date Inițiale'!$B$4) -> 13.25 | S17: =ABS(S18-'Date Inițiale'!$B$4) -> 11.25 | T17: =ABS(T18-'Date Inițiale'!$B$4) -> 9.25 | U17: =ABS(U18-'Date Inițiale'!$B$4) -> 7.25 | V17: =ABS(V18-'Date Inițiale'!$B$4) -> 5.75 | W17: =ABS(W18-'Date Inițiale'!$B$4) -> 4.75 | X17: =ABS(X18-'Date Inițiale'!$B$4) -> 3.75 | Y17: =ABS(Y18-'Date Inițiale'!$B$4) -> 2.75 | ... AC17: =ABS(AC18-'Date Inițiale'!$B$4) -> 1.25
A18: SF (Sfeclă de zahăr) | B18: 0 | C18: 0 | D18: 0 | E18: 0.1 | F18: 0.4 | G18: 0.6 | H18: 0.8 | I18: 0.9 | J18: 1 | K18: 1 | L18: 1 | M18: 0.9 | N18: 0.8 | P18: Temperatura | R18: -3 | S18: -1 | T18: 1 | U18: 3 | V18: 4.5 | W18: 5.5 | X18: 6.5 | Y18: 7.5 | Z18: 8.5 | AA18: 9.5 | AB18: 10.5 | AC18: 11.5
A19: SO (Soia) | B19: 0 | C19: 0 | D19: 0 | E19: 0 | F19: 0.1 | G19: 0.2 | H19: 0.4 | I19: 0.6 | J19: 0.9 | K19: 1 | L19: 1 | M19: 0.9 | N19: 0.8 | P19: 10%<P≤15% | Q19: N | R19: =ABS(R2/$R$1) -> 1 | S19: =ABS(S2/$S$1) -> 1 | T19: =ABS(T2/$T$1) -> 1 | U19: =ABS(U2/$U$1) -> 1 | V19: =ABS(V2/$V$1) -> 1 | W19: =ABS(W2/$W$1) -> 1 | X19: =ABS(X2/$X$1) -> 1 | Y19: =ABS(Y2/$Y$1) -> 1 | Z19: =ABS(Z2/$Z$1) -> 1 | AA19: =ABS(AA2/$AA$1) -> 1 | AB19: =ABS(AB2/$AB$1) -> 1 | AC19: =ABS(AC2/$AC$1) -> 1
A20: MF (Mazăre-fasole) | B20: 0 | C20: 0 | D20: 0 | E20: 0 | F20: 0.1 | G20: 0.4 | H20: 0.6 | I20: 0.8 | J20: 0.9 | K20: 1 | L20: 1 | M20: 1 | N20: 0.9 | Q20: E | R20: =ABS(R3/$R$1) -> 1 | S20: =ABS(S3/$S$1) -> 1 | T20: =ABS(T3/$T$1) -> 1 | U20: =ABS(U3/$U$1) -> 1 | V20: =ABS(V3/$V$1) -> 1 | W20: =ABS(W3/$W$1) -> 1 | X20: =ABS(X3/$X$1) -> 1 | Y20: =ABS(Y3/$Y$1) -> 1 | Z20: =ABS(Z3/$Z$1) -> 1 | AA20: =ABS(AA3/$AA$1) -> 1 | AB20: =ABS(AB3/$AB$1) -> 1 | AC20: =ABS(AC3/$AC$1) -> 1
A21: IU (In ulei) | B21: 0 | C21: 0 | D21: 0 | E21: 0 | F21: 0 | G21: 0.1 | H21: 0.3 | I21: 0.5 | J21: 0.9 | K21: 1 | L21: 1 | M21: 1 | N21: 0.9 | Q21: S | R21: =ABS(R4/$R$1) -> 1 | S21: =ABS(S4/$S$1) -> 1 | T21: =ABS(T4/$T$1) -> 1 | U21: =ABS(U4/$U$1) -> 1 | V21: =ABS(V4/$V$1) -> 1 | W21: =ABS(W4/$W$1) -> 1 | X21: =ABS(X4/$X$1) -> 1 | Y21: =ABS(Y4/$Y$1) -> 1 | Z21: =ABS(Z4/$Z$1) -> 1 | AA21: =ABS(AA4/$AA$1) -> 1.1052632 | AB21: =ABS(AB4/$AB$1) -> 1.0952381 | AC21: =ABS(AC4/$AC$1) -> 1.0869565
A22: IF (In fibre) | B22: 0 | C22: 0 | D22: 0.1 | E22: 0.3 | F22: 0.5 | G22: 0.7 | H22: 0.9 | I22: 1 | J22: 1 | K22: 1 | L22: 0.9 | M22: 0.7 | N22: 0.6 | Q22: V | R22: =ABS(R5/$R$1) -> 1 | S22: =ABS(S5/$S$1) -> 1 | T22: =ABS(T5/$T$1) -> 1 | U22: =ABS(U5/$U$1) -> 1 | V22: =ABS(V5/$V$1) -> 1 | W22: =ABS(W5/$W$1) -> 1 | X22: =ABS(X5/$X$1) -> 1 | Y22: =ABS(Y5/$Y$1) -> 1 | Z22: =ABS(Z5/$Z$1) -> 1 | AA22: =ABS(AA5/$AA$1) -> 1 | AB22: =ABS(AB5/$AB$1) -> 1 | AC22: =ABS(AC5/$AC$1) -> 1
A23: CN (Cânepă) | B23: 0 | C23: 0 | D23: 0 | E23: 0 | F23: 0.1 | G23: 0.2 | H23: 0.5 | I23: 0.7 | J23: 1 | K23: 1 | L23: 1 | M23: 0.9 | N23: 0.8 | P23: 15%<P≤20% | Q23: N | R23: =ABS(R6/$R$1) -> 1 | S23: =ABS(S6/$S$1) -> 1 | T23: =ABS(T6/$T$1) -> 1 | U23: =ABS(U6/$U$1) -> 1 | V23: =ABS(V6/$V$1) -> 1 | W23: =ABS(W6/$W$1) -> 1 | X23: =ABS(X6/$X$1) -> 1 | Y23: =ABS(Y6/$Y$1) -> 0.86666667 | Z23: =ABS(Z6/$Z$1) -> 0.88235294 | AA23: =ABS(AA6/$AA$1) -> 0.89473684 | AB23: =ABS(AB6/$AB$1) -> 0.9047619 | AC23: =ABS(AC6/$AC$1) -> 0.91304348
A24: LU (Lucernă) | B24: 0 | C24: 0 | D24: 0 | E24: 0 | F24: 0.1 | G24: 0.2 | H24: 0.4 | I24: 0.6 | J24: 0.9 | K24: 1 | L24: 1 | M24: 1 | N24: 0.9 | Q24: E | R24: =ABS(R7/$R$1) -> 1 | S24: =ABS(S7/$S$1) -> 1 | T24: =ABS(T7/$T$1) -> 1 | U24: =ABS(U7/$U$1) -> 1 | V24: =ABS(V7/$V$1) -> 1 | W24: =ABS(W7/$W$1) -> 1 | X24: =ABS(X7/$X$1) -> 1 | Y24: =ABS(Y7/$Y$1) -> 1 | Z24: =ABS(Z7/$Z$1) -> 1 | AA24: =ABS(AA7/$AA$1) -> 1 | AB24: =ABS(AB7/$AB$1) -> 1 | AC24: =ABS(AC7/$AC$1) -> 1
A25: TR (Trifoi) | B25: 0.1 | C25: 0.1 | D25: 0.2 | E25: 0.3 | F25: 0.5 | G25: 0.7 | H25: 0.9 | I25: 1 | J25: 1 | K25: 0.9 | L25: 0.8 | M25: 0.7 | N25: 0.6 | Q25: S | R25: =ABS(R8/$R$1) -> 1 | S25: =ABS(S8/$S$1) -> 1 | T25: =ABS(T8/$T$1) -> 1 | U25: =ABS(U8/$U$1) -> 1 | V25: =ABS(V8/$V$1) -> 1 | W25: =ABS(W8/$W$1) -> 1.1818182 | X25: =ABS(X8/$X$1) -> 1.1538462 | Y25: =ABS(Y8/$Y$1) -> 1.1333333 | Z25: =ABS(Z8/$Z$1) -> 1.1176471 | AA25: =ABS(AA8/$AA$1) -> 1.1052632 | AB25: =ABS(AB8/$AB$1) -> 1.0952381 | AC25: =ABS(AC8/$AC$1) -> 1.0869565
A26: LG (Legume) | B26: 0 | C26: 0 | D26: 0 | E26: 0.3 | F26: 0.5 | G26: 0.8 | H26: 0.9 | I26: 1 | J26: 1 | K26: 1 | L26: 1 | M26: 1 | N26: 0.9 | Q26: V | R26: =ABS(R9/$R$1) -> 1 | S26: =ABS(S9/$S$1) -> 1 | T26: =ABS(T9/$T$1) -> 1 | U26: =ABS(U9/$U$1) -> 1 | V26: =ABS(V9/$V$1) -> 1 | W26: =ABS(W9/$W$1) -> 1 | X26: =ABS(X9/$X$1) -> 1 | Y26: =ABS(Y9/$Y$1) -> 1 | Z26: =ABS(Z9/$Z$1) -> 1.1176471 | AA26: =ABS(AA9/$AA$1) -> 1.1052632 | AB26: =ABS(AB9/$AB$1) -> 1.0952381 | AC26: =ABS(AC9/$AC$1) -> 1.0869565
P27: 20%<P≤25% | Q27: N | R27: =ABS(R10/$R$1) -> 1 | S27: =ABS(S10/$S$1) -> 3 | T27: =ABS(T10/$T$1) -> 1 | U27: =ABS(U10/$U$1) -> 0.33333333 | V27: =ABS(V10/$V$1) -> 0.66666667 | W27: =ABS(W10/$W$1) -> 0.81818182 | X27: =ABS(X10/$X$1) -> 0.84615385 | Y27: =ABS(Y10/$Y$1) -> 0.86666667 | Z27: =ABS(Z10/$Z$1) -> 0.88235294 | AA27: =ABS(AA10/$AA$1) -> 0.89473684 | AB27: =ABS(AB10/$AB$1) -> 0.9047619 | AC27: =ABS(AC10/$AC$1) -> 0.91304348
Q28: E | R28: =ABS(R11/$R$1) -> 0 | S28: =ABS(S11/$S$1) -> 0 | T28: =ABS(T11/$T$1) -> 0 | U28: =ABS(U11/$U$1) -> 0 | V28: =ABS(V11/$V$1) -> 0 | W28: =ABS(W11/$W$1) -> 0 | X28: =ABS(X11/$X$1) -> 0 | Y28: =ABS(Y11/$Y$1) -> 0 | Z28: =ABS(Z11/$Z$1) -> 0 | AA28: =ABS(AA11/$AA$1) -> 0 | AB28: =ABS(AB11/$AB$1) -> 0 | AC28: =ABS(AC11/$AC$1) -> 0
Q29: S | R29: =ABS(R12/$R$1) -> 0 | S29: =ABS(S12/$S$1) -> 0 | T29: =ABS(T12/$T$1) -> 0 | U29: =ABS(U12/$U$1) -> 0 | V29: =ABS(V12/$V$1) -> 0 | W29: =ABS(W12/$W$1) -> 0 | X29: =ABS(X12/$X$1) -> 0 | Y29: =ABS(Y12/$Y$1) -> 0 | Z29: =ABS(Z12/$Z$1) -> 0 | AA29: =ABS(AA12/$AA$1) -> 0 | AB29: =ABS(AB12/$AB$1) -> 0 | AC29: =ABS(AC12/$AC$1) -> 0
Q30: V | R30: =ABS(R13/$R$1) -> 0 | S30: =ABS(S13/$S$1) -> 0 | T30: =ABS(T13/$T$1) -> 0 | U30: =ABS(U13/$U$1) -> 0 | V30: =ABS(V13/$V$1) -> 0 | W30: =ABS(W13/$W$1) -> 0 | X30: =ABS(X13/$X$1) -> 0 | Y30: =ABS(Y13/$Y$1) -> 0 | Z30: =ABS(Z13/$Z$1) -> 0 | AA30: =ABS(AA13/$AA$1) -> 0 | AB30: =ABS(AB13/$AB$1) -> 0 | AC30: =ABS(AC13/$AC$1) -> 0
P32: Row Index | S32: =HLOOKUP(MROUND('Date Inițiale'!B4,0.5),'Temperatura medie anuală'!R18:AC30,1,1) -> 10.5
P33: =IF('Date Inițiale'!B3=Panta!D2,2,IF('Date Inițiale'!B3=Panta!E2,6,IF('Date Inițiale'!B3=Panta!F2,10,0))) -> 0 | Q33: =IF('Date Inițiale'!D3="N",0,IF('Date Inițiale'!D3="E",1,IF('Date Inițiale'!D3="S",2,IF('Date Inițiale'!D3="V",3,0)))) -> 2
V34: 5.5 | W34: 6.5 | X34: 7.5 | Y34: =AVERAGE(V34:X34) -> 6.5 | Z34: t. med. | AA34: =(V34-W34)/V34*Y37+(X34-W34)/X34*Y37 -> -0.056124885 | AB34: =AVERAGE(V35+V35*AA34,X35-X35*AA34) -> 1.1562152 | AC34: =1-W35/AB34 -> 0.002048927
P35: Min value + count | V35: 1.1818182 | W35: 1.1538462 | X35: 1.1333333 | Y35: =AVERAGE(V35:X35) -> 1.1563326 | Z35: t. med. corect. (?) | AC35: =1-W35/Y37 -> 0.003221909
P36: =MIN(R17:AC17) -> 0.25 | Q36: =COUNTIF(R17:AC17,MIN(R17:AC17)) -> 1 | W36: 5.5 | X36: 7.5 | Y36: =AVERAGE(V36:X36) -> 6.5 | Z36: t. med.
W37: 1.1818182 | X37: 1.1333333 | Y37: =AVERAGE(V37:X37) -> 1.1575758 | Z37: t. med. corect.
P38: Temperaturile
P39: =HLOOKUP(MIN(R17:AC17),R17:AC30,2,0) -> 10.5 | Q39: =HLOOKUP(_xlfn.MINIFS(R17:AC17,R17:AC17,">"&P36),R17:AC30,2,0) -> #NAME?
P41: Cf. de corecție
P42: =HLOOKUP(P39,R18:AC30,P33+Q33,0) -> 1

Sheet Precipitații
A1: Cultura | B1: Precipitații, mm (≤8° temp. an. med.) | K1: Precipitații, mm (8<X<10° temp. an. med.) | T1: Precipitații, mm (≥10° temp. an. med.)
B2: 250 | C2: 350 | D2: 425 | E2: 475 | F2: 525 | G2: 575 | H2: 650 | I2: 750 | J2: 900 | K2: 250 | L2: 350 | M2: 425 | N2: 475 | O2: 525 | P2: 575 | Q2: 650 | R2: 750 | S2: 900 | T2: 250 | U2: 350 | V2: 425 | W2: 475 | X2: 525 | Y2: 575 | Z2: 650 | AA2: 750 | AB2: 900
A3: PS (Pășuni) | B3: 0.7 | C3: 0.8 | D3: 0.8 | E3: 0.9 | F3: 0.9 | G3: 1 | H3: 1 | I3: 1 | J3: 1 | K3: 0.5 | L3: 0.6 | M3: 0.7 | N3: 0.7 | O3: 0.8 | P3: 0.9 | Q3: 0.9 | R3: 1 | S3: 1 | T3: 0.3 | U3: 0.4 | V3: 0.5 | W3: 0.7 | X3: 0.8 | Y3: 0.8 | Z3: 0.9 | AA3: 1 | AB3: 1
A4: FN (Fânețe) | B4: 0.6 | C4: 0.7 | D4: 0.7 | E4: 0.8 | F4: 0.8 | G4: 1 | H4: 1 | I4: 1 | J4: 1 | K4: 0.4 | L4: 0.5 | M4: 0.6 | N4: 0.7 | O4: 0.7 | P4: 0.8 | Q4: 0.9 | R4: 1 | S4: 1 | T4: 0.2 | U4: 0.3 | V4: 0.4 | W4: 0.6 | X4: 0.7 | Y4: 0.7 | Z4: 0.8 | AA4: 0.9 | AB4: 1
A5: MR (Măr) | B5: 0.5 | C5: 0.6 | D5: 0.7 | E5: 0.8 | F5: 0.9 | G5: 1 | H5: 1 | I5: 1 | J5: 0.9 | K5: 0.4 | L5: 0.5 | M5: 0.7 | N5: 0.8 | O5: 0.9 | P5: 1 | Q5: 1 | R5: 0.9 | S5: 0.8 | T5: 0.3 | U5: 0.4 | V5: 0.6 | W5: 0.7 | X5: 0.8 | Y5: 0.9 | Z5: 1 | AA5: 1 | AB5: 1
A6: PR (Păr) | B6: 0.5 | C6: 0.6 | D6: 0.8 | E6: 1 | F6: 1 | G6: 1 | H6: 1 | I6: 0.9 | J6: 0.7 | K6: 0.5 | L6: 0.6 | M6: 0.7 | N6: 0.9 | O6: 1 | P6: 1 | Q6: 1 | R6: 0.8 | S6: 0.8 | T6: 0.4 | U6: 0.5 | V6: 0.7 | W6: 0.8 | X6: 0.9 | Y6: 1 | Z6: 1 | AA6: 1 | AB6: 1
